Workbook

Sheet R0581～
B1: 東京製鐵
B4: ２０２４（Ｒ６）年６月１１日〜 | AA4: 中部
B5: 中山製鋼 | C5: 中山製鋼 | D5: 中山製鋼 | E5: 中山鋼業 | G5: 合同大阪 | I5: 産振ﾔｰﾄﾞ | J5: 大鉄 堺 | P5: 岸和田 | S5: ﾔﾏﾄ | T5: 山陽特殊 | V5: ｸﾎﾞﾀ | W5: 愛知 | Z5: 東京製鐵 | AD5: 山口鋼業 | AG5: 大同特殊 | AL5: RTA | AM5: 大一産業 | AN5: トピー工業 | AO5: 衣浦 | AP5: 日鉄 ｽﾁｰﾙ | AQ5: 栗本鐵工 | AR5: 韓国輸出 | AS5: 大谷製鉄 | AT5: 銑ダライ | AU5: 大阪鋼業 | AW5: 東鉄岡山 | AX5: ＪＦＥ条鋼 | AZ5: 南港 | BB5: 北港 | BC5: 泉北中谷 | BF5: 泉北大都 | BG5: 大阪港埠頭 | BH5: ﾆｭｰｽｺﾝ尼崎 | BI5: ﾆｭｰｽｺﾝ稲永 | BJ5: 共英枚方 | BM5: 共英名古屋 | BN5: 新日鉄住金和歌山 | BQ5: オオハラ尼崎 | BR5: 信和商事 | BS5: ｴｺﾌﾟﾗﾝﾆﾝｸﾞ | BT5: 名古屋港 | BW5: トヨキン | BX5: 寺田
A6: 品目 | B6: 阪和 | C6: 豊通 | E6: ナベ | G6: 伊藤忠 | H6: 阪和 | I6: 産振 | J6: 大鉄堺 | K6: 豊通 | L6: 産振 | N6: 伊藤忠 | P6: 豊通 | R6: リバイブ | S6: 阪和 | T6: 産振 | U6: MM | V6: 伊藤忠 | W6: 阪和 | X6: ナベ | Z6: 関西 | AA6: 岡山 | AB6: 名古屋 | AC6: 田原 | AD6: MM建材 | AF6: 阪和 | AG6: 大同興業 | AI6: JSE | AL6: RTA | AM6: ナベ | AN6: ＭＭ | AO6: 産振 | AP6: 産振 | AQ6: 豊通 | AR6: 豊通大都 | AS6: ナベ | AT6: ナベ | AU6: ナベ | AV6: リバイブ | AW6: ナベ | AX6: リバイブ | AY6: 阪和 | AZ6: ﾅﾝｾｲ | BA6: 産振 | BB6: ナベ | BC6: 産振 | BD6: ナベ双葉 | BE6: 豊商双葉 | BF6: 産振 | BG6: 日鉄物産 | BH6: ナベ | BJ6: ナベ | BN6: 伊藤忠 | BO6: ＭＭ | BP6: 産振 | BQ6: ナベ | BR6: 豊通 | BT6: 水野産業 | BU6: 阪和西三区 | BV6: ＭＭ | BW6: ナベ 大同特殊 H2ｽﾗｲﾄﾞ
A7: スポット期間 | D7: 中川 ＆ 出張 | O7: ｽﾎﾟｯﾄ | P7: 6/8&10 | U7: 5月度 300ｔ | X7: 5/11~31 ｽﾎﾟｯﾄ 150t | Y7: 置場 | Z7: 直納 | AB7: 直納 | AC7: 直納 | AG7: 運賃込単価/置場-2 | AH7: 持込 | AI7: 大和ﾘﾃｯｸ | AJ7: 第二 ＠2.3 岐阜 ＠1.5 | AL7: 置場単価 | AN7: 置場単価 | AO7: 4月～ 6月 | AP7: 置場 単価 | AR7: 完納 | AS7: 置場単価 | AT7: 置場単価 | AX7: 運賃2.5 | BJ7: 置場単価 | BK7: 5/7～ 京都置場 | BL7: リバイブ京都置場 | BN7: 200ｔ | BT7: 西三区 | BU7: 9/7～100ｔ | BV7: 7/1～
A8: ＨＳ１(電特A) | G8: 52.8 | R8: 運賃 | T8: 54.6 | U8: 57 | W8: 54.2 | X8: 50.5 | Y8: 52 | Z8: 53.5 | AB8: 51 | AC8: 52 | AE8: 50.5 | AF8: 51 | AG8: 普HS | AI8: HS | AJ8: 第2 | AO8: 54 | AQ8: 57.3 | AR8: 28.8 | AS8: 電特A | AW8: ﾒｯｷ | BA8: 53 | BD8: 53.5 | BH8: 52.3 | BI8: 52.5 | BW8: 銑ダ | BX8: 銑ダ
A9: ＨＳ２ | B9: 54.4 | G9: 52.3 | R9: 1.8 | T9: 54.4 | U9: 56.8 | W9: 53.7 | X9: 50 | Y9: 51.5 | AE9: 故銑 | AG9: 置場 | AH9: 54 | AI9: 54.8 | AJ9: 51.9 | AQ9: 57 | AS9: 49.5 | AW9: ﾛｰﾙ | BA9: 中谷
A10: ＨＳ３ | T10: 52.4 | U10: 54.8 | AE10: 50.5 | AJ10: 岐阜 | AQ10: 56.1 | AS10: 置場 | AW10: 16.5 | BW10: 引取
A11: Ｈ１/ｻﾑﾃｯｸ | B11: 54.4 | C11: 54.3 | AJ11: 52.7 | AW11: ? | AX11: 持込 | BG11: 52 | BW11: 単価
A12: Ｈ１(特A) | B12: 52 | C12: 52 | E12: 54 | G12: 53.8 | J12: 54.5 | K12: 39.4 | L12: 53.7 | N12: 38.8 | P12: 55.5 | Q12: 53.5 | S12: 52.6 | W12: 49.2 | Y12: 51 | Z12: 53 | AB12: 49.2 | AC12: 51.2 | AF12: 49.5 | AG12: 置場 | AR12: 26.8 | AX12: 52 | BH12: 51.5 | BJ12: 51 | BK12: 52.5 | BM12: 53.2 | BN12: 51
A13: ＪＨ１ | J13: 53 | K13: 38.4 | N13: 45.7 | AD13: 鉄筋 | AG13: ▲2.3 | AI13: H2~H4 | AX13: 持込
A14: Ｈ２(特級) | B14: 47.3 | C14: 47.3 | E14: 52.5 | G14: 52.3 | J14: 51 | K14: 35.2 | N14: 43.5 | P14: 54.5 | Q14: 51.5 | S14: 51.6 | W14: 48.7 | Y14: 49.4 | Z14: 51.5 | AB14: 48.5 | AC14: 49.5 | AD14: 50 | AE14: 49 | AF14: 49 | AH14: 50.5 | AI14: 49.7 | AJ14: 第2 | AN14: 43 | AP14: 京都 | AR14: 25.5 | AX14: 51 | AZ14: 49.5 | BB14: 49.5 | BD14: 49.5 | BH14: 50.5 | BJ14: 49.5 | BK14: 50 | BL14: 一括 | BM14: 50.5 | BN14: 46 | BQ14: 33 | BT14: 32
A15: Ｈ３(1級) | B15: 43.3 | C15: 43.3 | D15: 中川 | E15: 50.5 | G15: 51.8 | J15: 50.5 | K15: 34.2 | N15: 42.5 | Q15: 51 | S15: 50.6 | W15: 47.7 | Y15: 48.4 | Z15: 51.5 | AB15: 48 | AC15: 49 | AE15: 48 | AF15: 48 | AH15: 50 | AJ15: 47.4 | AX15: 50 | BH15: 49 | BJ15: 49 | BK15: 50 | BL15: 50? | BM15: 49.5
A16: Ｌ１(2級) | B16: 36.8 | C16: 36.8 | D16: 嘉弘 | E16: 50 | G16: 50.8 | J16: 50 | K16: 32.7 | N16: 41.5 | Q16: 50.5 | S16: 48.6 | U16: 1 | Z16: 49.5 | AB16: 46.5 | AC16: 47.5 | AJ16: 岐阜 | AP16: 大阪 | AX16: 46.8 | BJ16: 49 | BK16: 50 | BL16: 50? | BM16: 46.5 | BU16: 錫ﾒｯｷ
A17: Ｌ２(H4･級外) | D17: ▲3 | E17: L1ﾊﾞﾗ | J17: 0 | S17: 46.1 | W17: 44.3 | Y17: 44.4 | Z17: 46.5 | AB17: 43.5 | AC17: 44.5 | AE17: 46.5 | AF17: 46.5 | AH17: 49.5 | AJ17: 48.2 | AX17: 40.9 | BB17: 大阪 | BU17: 36.5 | BV17: ？
A18: 新断Ａ | B18: 55.3 | C18: 55.3 | D18: 52.3 | E18: 40 | G18: 53.3 | J18: 37.5 | K18: 35.7 | N18: 37.3 | U18: 55 | V18: 58.2 | W18: 52.5 | AC18: 50.5 | AX18: 53 | BB18: 置場 | BD18: 52.5 | BI18: 53.5 | BV18: 39
A19: 新断Ｂ | B19: 54.3 | C19: 54.3 | D19: 出張 | G19: 52.8 | J19: 37 | K19: 35.2 | N19: 36.8 | U19: 54 | W19: 51.5 | AQ19: 鋳鉄管 | AX19: 52 | BB19: 0.8
A20: 新断Ｐ | D20: ▲1 | R20: 置場 | U20: 新断C | Y20: ？？ | AG20: 置場 | AL20: 栗東 | AM20: 鋳物 | AQ20: 52.8 | AU20: 持込 | AX20: 持込 | BB20: 第二 | BJ20: 第二
A21: ダライＡ | D21: 54.3 | E21: 46.7 | G21: 42.8 | J21: 37 | K21: 36.7 | U21: 51.7 | Y21: 48 | AC21: 48 | AE21: 47.6 | AF21: 41.5 | AG21: 46.9 | AL21: 48 | AM21: 45.5 | AU21: 44 | AX21: 41 | BB21: 運賃 | BJ21: 36.3 | BT21: 33？
A22: ダライＢ | G22: 40.8 | J22: 37 | K22: 36.7 | AL22: 第二 | AM22: ﾀﾞｸﾀｲﾙ | BB22: 2.2
A23: 銑ダライ
A24: シュレＡ | J24: 39.5 | K24: 38.7 | W24: 52.5 | Z24: 53.5 | AB24: 49.5 | AC24: 50.5 | AL24: 48.5 | AM24: 40 | AT24: 銑ﾀﾞﾗｲ | BC24: 荷止 | BJ24: 大阪CP
A25: シュレＢ | J25: 38.8 | K25: 38 | AG25: 火力 | AT25: 46 | AU25: 銑ダライ | BJ25: 27
A26: シュレＣ | J26: 37.4 | K26: 36.6 | Z26: 52.5 | AB26: 49 | AC26: 50 | AG26: ﾓﾘﾌﾞﾃﾞﾝ | AX26: 置場 | BJ26: 栗東CP
A27: ＣＰ Ａ | J27: 40.5 | K27: 44.7 | L27: 51 | Q27: 53.7 | AC27: 48 | AG27: 1~2% | AU27: 持込 | AX27: 52.5 | BJ27: 50.5 | BR27: 33.2 | BS27: 33.2
A28: ＣＰ Ｂ一斗缶 | J28: 38 | K28: 42.2 | L28: 44.7 | AG28: 40
A29: ＣＨＡ足廻 | AG29: 置場
A30: ＣＨＢ足廻
A31: 雑品 | B31: ■東洋トレーディング＠８０（４/４：置場） ■津和商事＠６８（１１／１７：置場） ■ＧＲＭ＠７０（１２／３：置場） ■岡田金属／京都＠７１（１１／２４：置場） ■東昌商事＠（持込み）
B32: ■振洋産業＠４７（８／５）
A33: 配電盤 | B33: ■ＧＲＭ（旧中西産業）＠１１０（９／１６：置場） ■東洋トレーディング＠９５（４/１０：置場） ■津和商事＠８０（１２／７：置場） ■岡田金属／京都＠７６（３／３１：置場） ■東昌商事＠１１０（９/１２：置場）大阪＠１１５（置場）
A34: 工業系ｴｱｺﾝ | B34: ■津和商事＠１４５【室内機＆室外機共】（７／１）、＠１３０【ビルトイン】、＠１２０【ガスヒーポン】 ■岡田金属／京都＠１５５【外機】＠？【内機】（１１／２９：置場） ■日中商事【外機】＠１７５（２／２８）【ｶﾞｽﾋｰﾎﾟﾝ】＠１２５（２／２８）
B35: ■ＧＲＭ（旧中西産業）＠１６０【外機】＠１４０【内機】＠？【スポットクーラー】（９/１６）＠１１０【チラー】（７/５）＠１５０【ＧＨＰ：油60kgUP】（１２/６） ■東洋トレーディング外機＠１７０、ＧＨＰ＠１３０、内機＠１００（８/２９）
A36: トランス | B36: 津和商事 ■銅＠６５ ■銅コア＠８５ ■アルミ＠３０ ■アルミコア＠４５ （Ｈ２８／１０／１４付）
B37: 中西産業 ■銅＠ ■銅コア＠ ■アルミ＠１８ ■アルミコア＠ ■MIX＠ （Ｒ０２／１０／１３付）
B38: ナベショー ■銅＠６９ ■銅コア＠１０９ ■アルミ＠２９ ■アルミコア＠３４ ■MIX＠４９ （Ｈ２８／１０／１４付）
A39: ステンレス | B39: 阪神金属 ■ステン３０４＠２００（５/２７）持込+＠3 ■ステンダライ＠１８０（ｲﾝｻｲｽﾞ▲２０）持込+＠3 ■解体ステン＠１８５～＠１７０（ｲﾝｻｲｽﾞ▲１５～▲３０） ■ステン３０１＠１８５（ｲﾝｻｲｽﾞ▲１５） ■ステン６３０【Ni&Cuが高いのでメーカー不人気】＠６８（１０／３０）
B40: 阪神金属 ■ステン３１６＠２７０（１０／７） ■ステン３１０＠３２０～＠３３０（７／９） ■Ｈｉクローム＠５７（２０２２／７／１９） ■ステン４３０＠３２（2021/1/13川本社長問合せ：SUS403MIX）
B41: ナベショー＠１８５（９／６） ステンダライ＠１７５（インサイズ▲１０／10ｔﾍﾞｰｽならﾀﾞﾗｲ▲３） ＯＳ（ｓ１％：インサイズ▲２０～５０） 新プラントステンレス＠９２（７／１３） クローム（４３０）＠２３（７／９問合せ）
B42: ＧＲＭ（旧中西産業）／親和スチール＠１７８（南港持込：9/7付：前回7/26+3：運賃▲３．０）ステンダライ＠１６３～１５３（ｲﾝｻｲｽﾞ▲15＆▲20＆▲25混じりによって変更） 解体ステン＠１７３（ｲﾝｻｲｽﾞ▲20？：３/７付）
...

Sheet 最新単価表
B1: 東鐵関西:直納 | C1: 中山製鋼:阪和 | D1: 中山製鋼:豊通 | E1: 中山製鋼:豊通/出張商店 | F1: 中山製鋼:豊通/中川嘉弘商店 | G1: 中山鋼業:ナベ | H1: 合同大阪:伊藤忠 | I1: 合同大阪:阪和 | J1: 産振ﾔｰﾄﾞ:産振 | K1: 大鉄 堺:大鉄堺 | L1: 大鉄 堺:豊通 | M1: 大鉄 堺:産振 | N1: 大鉄 堺:伊藤忠 | O1: 大鉄 堺:ナベ | P1: 岸和田:豊通 | Q1: 岸和田:阪和 | R1: 岸和田:岡谷鋼機 | S1: 岸和田:リバイブ | T1: ｸﾎﾞﾀ:伊藤忠 | U1: 栗本鐵工:豊通 | V1: 共英枚方:ナベ/置場単価 | W1: 共英枚方:ナベ/5/7～京都置場 | X1: 共英枚方:リバイブ京都置場 | Y1: 南港:ﾅﾝｾｲ | Z1: 南港:産振 | AA1: 北港:リバイブ | AB1: 北港:ナベ | AC1: 泉北中谷:産振 | AD1: 泉北中谷:豊通 | AE1: 泉北中谷:ナベ双葉 | AF1: 泉北大都:産振 | AG1: 泉北大都:リバイブ | AH1: 泉北大都:GRM | AI1: ﾆｭｰｽｺﾝ尼崎:ナベ | AJ1: 大阪鋼業:ナベ | AK1: 大阪鋼業:リバイブ | AL1: 大阪港埠頭:日鉄物産 | AM1: 東鐵岡山:直納 | AN1: ﾏｷｳﾗ鋼業:直納 | AO1: ﾔﾏﾄ:阪和 | AP1: 合同姫路:阪和 | AQ1: 山陽特殊:産振 | AR1: 山陽特殊:MM | AS1: 山陽特殊:大同 | AT1: ＪＦＥ条鋼:リバイブ | AU1: ＪＦＥ条鋼:阪和 | AV1: 東鐵名古屋:直納 | AW1: 東鐵田原:直納 | AX1: 愛知:阪和 | AY1: 愛知:ナベ | AZ1: 山口鋼業:MM建材 | BA1: 山口鋼業:阪和 | BB1: 大同特殊鋼:大同興業 | BC1: 大同特殊鋼:JSE/大和ﾘﾃｯｸ | BD1: 大同特殊鋼:JSE/第二＠2.3 | BE1: 大同特殊鋼:JSE/岐阜＠1.5 | BF1: 衣浦:産振 | BG1: トピー工業:ＭＭ | BH1: RTA:栗東置場単価 | BI1: RTA:第二置場単価 | BJ1: ﾆｭｰｽｺﾝ稲永:ナベ | BK1: 共英名古屋:ナベ | BL1: 大谷製鉄:ナベ | BM1: 銑ダライ:ナベ | BN1: 大一産業:ナベ | BO1: 日鉄ｽﾁｰﾙ:産振 | BP1: 新日鉄住金和歌山:伊藤忠 | BQ1: 新日鉄住金和歌山:ＭＭ | BR1: 新日鉄住金和歌山:産振 | BS1: 韓国輸出:豊通大都 | BT1: オオハラ尼崎:ナベ | BU1: 名古屋港:水野産業 | BV1: 名古屋港:阪和西三区 | BW1: 名古屋港:ＭＭ | BX1: トヨキン:ナベ・大同特殊・H2ｽﾗｲﾄﾞ | BY1: 寺田:ナベ・大同特殊・H2ｽﾗｲﾄﾞ
A2: 2026(R8)年4月16日～ | B2: 関 西 方 面 | AM2: 姫路方面 | AV2: 愛 知 方 面 | BL2: そ の 他
A3: 製鋼メーカー | B3: 東鐵関西 | C3: 中山製鋼 | G3: 中山鋼業 | H3: 合同大阪 | J3: 産振ﾔｰﾄﾞ | K3: 大鉄 堺 | P3: 岸和田 | T3: ｸﾎﾞﾀ | U3: 栗本鐵工 | V3: 共英枚方 | Y3: 南港 | AA3: 北港 | AC3: 泉北中谷 | AF3: 泉北大都 | AI3: ﾆｭｰｽｺﾝ尼崎 | AJ3: 大阪鋼業 | AL3: 大阪港埠頭 | AM3: 東鐵岡山 | AN3: ﾏｷｳﾗ鋼業 | AO3: ﾔﾏﾄ | AP3: 合同姫路 | AQ3: 山陽特殊 | AT3: ＪＦＥ条鋼 | AV3: 東鐵名古屋 | AW3: 東鐵田原 | AX3: 愛知 | AZ3: 山口鋼業 | BB3: 大同特殊鋼 | BF3: 衣浦 | BG3: トピー工業 | BH3: RTA | BJ3: ﾆｭｰｽｺﾝ稲永 | BK3: 共英名古屋 | BL3: 大谷製鉄 | BM3: 銑ダライ | BN3: 大一産業 | BO3: 日鉄 ｽﾁｰﾙ | BP3: 新日鉄住金和歌山 | BS3: 韓国輸出 | BT3: オオハラ尼崎 | BU3: 名古屋港 | BX3: トヨキン | BY3: 寺田
A4: 商 社 | B4: 直納 | C4: 阪和 | D4: 豊通 | G4: ナベ | H4: 伊藤忠 | I4: 阪和 | J4: 産振 | K4: 大鉄堺 | L4: 豊通 | M4: 産振 | N4: 伊藤忠 | O4: ナベ | P4: 豊通 | Q4: 阪和 | R4: 岡谷鋼機 | S4: リバイブ | T4: 伊藤忠 | U4: 豊通 | V4: ナベ | Y4: ﾅﾝｾｲ | Z4: 産振 | AA4: リバイブ | AB4: ナベ | AC4: 産振 | AD4: 豊通 | AE4: ナベ双葉 | AF4: 産振 | AG4: リバイブ | AH4: GRM | AI4: ナベ | AJ4: ナベ | AK4: リバイブ | AL4: 日鉄物産 | AM4: 直納 | AN4: 直納 | AO4: 阪和 | AP4: 阪和 | AQ4: 産振 | AR4: MM | AS4: 大同 | AT4: リバイブ | AU4: 阪和 | AV4: 直納 | AW4: 直納 | AX4: 阪和 | AY4: ナベ | AZ4: MM建材 | BA4: 阪和 | BB4: 大同興業 | BC4: JSE | BF4: 産振 | BG4: ＭＭ | BH4: RTA | BJ4: ナベ | BL4: ナベ | BM4: ナベ | BN4: ナベ | BO4: 産振 | BP4: 伊藤忠 | BQ4: ＭＭ | BR4: 産振 | BS4: 豊通大都 | BT4: ナベ | BU4: 水野産業 | BV4: 阪和西三区 | BW4: ＭＭ | BX4: ナベ 大同特殊 H2ｽﾗｲﾄﾞ
A5: 備 考 | E5: 出張商店 ▲1 | F5: 中川嘉弘商店 ▲3 | J5: ＣＰのみ東鐵ｽﾗｲﾄﾞ | O5: 置場 単価 | R5: ｴｺﾒﾀﾙ ﾘﾀｰﾝ分 | S5: 運賃 1.8 | V5: 置場単価 | X5: リバイブ京都置場 | Y5: 大都Ｊ1 | AB5: 大阪▲0.8 第2 ▲2.2 | AD5: 泉北助松埠頭 | AK5: 東鐵岡山ｽﾗｲﾄﾞ | AR5: 2月度 200t | AS5: 4月度 200t | AT5: 運賃 置場 ▲2.5 | AV5: ナベ置場▲2.0 | AW5: ナベ置場▲2.4 | AX5: 4月度 ｽﾎﾟｯﾄ 300t～ | AY5: 置場 東鐵ｽﾗｲﾄﾞ | BA5: 下記単価不明 | BB5: 持込 | BC5: 大和ﾘﾃｯｸ | BD5: 第二 ＠2.3 | BE5: 岐阜 ＠1.5 | BG5: 置場単価 | BH5: 栗東置場単価 | BI5: 第二置場単価 | BL5: 置場単価 | BM5: 置場単価 | BO5: 置場 単価 | BP5: 200ｔ | BS5: 完納 | BU5: 西三区 | BV5: 9/7～100ｔ | BW5: 7/1～
A6: スポットなど | D6: 新断 | G6: 期間 | M6: 期間 | P6: 期間 | Z6: 期間 | AR6: 期間 | AX6: 57.5 | BC6: 東海 | BF6: ＨＳ
D7: 泉北 | P7: 59 | Z7: 大都 | AX7: 57 | BC7: ＨＳ
P8: 58 | AX8: 52.5
P9: 55 | AX9: 52
AX10: 51
A11: ＨＳ１(単体H1/電特A/HS)) | B11: =IF(MAXIFS('単価履歴'!$H:$H,'単価履歴'!$E:$E,B$1,'単価履歴'!$F:$F,$A11,'単価履歴'!$O:$O, MAXIFS('単価履歴'!$O:$O,'単価履歴'!$E:$E,B$1,'単価履歴'!$F:$F,$A11))=0,"", MAXIFS('単価履歴'!$H:$H,'単価履歴'!$E:$E,B$1,'単価履歴'!$F:$F,$A11,'単価履歴'!$O:$O, MAXIFS('単価履歴'!$O:$O,'単価履歴'!$E:$E,B$1,'単価履歴'!$F:$F,$A11))) -> 55.5 | D11: =IF(MAXIFS('単価履歴'!$H:$H,'単価履歴'!$E:$E,D$1,'単価履歴'!$F:$F,$A11,'単価履歴'!$O:$O, MAXIFS('単価履歴'!$O:$O,'単価履歴'!$E:$E,D$1,'単価履歴'!$F:$F,$A11))=0,"", MAXIFS('単価履歴'!$H:$H,'単価履歴'!$E:$E,D$1,'単価履歴'!$F:$F,$A11,'単価履歴'!$O:$O, MAXIFS('単価履歴'!$O:$O,'単価履歴'!$E:$E,D$1,'単価履歴'!$F:$F,$A11))) -> 57.3 | H11: =IF(MAXIFS('単価履歴'!$H:$H,'単価履歴'!$E:$E,H$1,'単価履歴'!$F:$F,$A11,'単価履歴'!$O:$O, MAXIFS('単価履歴'!$O:$O,'単価履歴'!$E:$E,H$1,'単価履歴'!$F:$F,$A11))=0,"", MAXIFS('単価履歴'!$H:$H,'単価履歴'!$E:$E,H$1,'単価履歴'!$F:$F,$A11,'単価履歴'!$O:$O, MAXIFS('単価履歴'!$O:$O,'単価履歴'!$E:$E,H$1,'単価履歴'!$F:$F,$A11))) -> 55.8 | O11: =IF(MAXIFS('単価履歴'!$H:$H,'単価履歴'!$E:$E,O$1,'単価履歴'!$F:$F,$A11,'単価履歴'!$O:$O, MAXIFS('単価履歴'!$O:$O,'単価履歴'!$E:$E,O$1,'単価履歴'!$F:$F,$A11))=0,"", MAXIFS('単価履歴'!$H:$H,'単価履歴'!$E:$E,O$1,'単価履歴'!$F:$F,$A11,'単価履歴'!$O:$O, MAXIFS('単価履歴'!$O:$O,'単価履歴'!$E:$E,O$1,'単価履歴'!$F:$F,$A11))) | P11: =IF(MAXIFS('単価履歴'!$H:$H,'単価履歴'!$E:$E,P$1,'単価履歴'!$F:$F,$A11,'単価履歴'!$O:$O, MAXIFS('単価履歴'!$O:$O,'単価履歴'!$E:$E,P$1,'単価履歴'!$F:$F,$A11))=0,"", MAXIFS('単価履歴'!$H:$H,'単価履歴'!$E:$E,P$1,'単価履歴'!$F:$F,$A11,'単価履歴'!$O:$O, MAXIFS('単価履歴'!$O:$O,'単価履歴'!$E:$E,P$1,'単価履歴'!$F:$F,$A11))) | Q11: =IF(MAXIFS('単価履歴'!$H:$H,'単価履歴'!$E:$E,Q$1,'単価履歴'!$F:$F,$A11,'単価履歴'!$O:$O, MAXIFS('単価履歴'!$O:$O,'単価履歴'!$E:$E,Q$1,'単価履歴'!$F:$F,$A11))=0,"", MAXIFS('単価履歴'!$H:$H,'単価履歴'!$E:$E,Q$1,'単価履歴'!$F:$F,$A11,'単価履歴'!$O:$O, MAXIFS('単価履歴'!$O:$O,'単価履歴'!$E:$E,Q$1,'単価履歴'!$F:$F,$A11))) | R11: =IF(MAXIFS('単価履歴'!$H:$H,'単価履歴'!$E:$E,R$1,'単価履歴'!$F:$F,$A11,'単価履歴'!$O:$O, MAXIFS('単価履歴'!$O:$O,'単価履歴'!$E:$E,R$1,'単価履歴'!$F:$F,$A11))=0,"", MAXIFS('単価履歴'!$H:$H,'単価履歴'!$E:$E,R$1,'単価履歴'!$F:$F,$A11,'単価履歴'!$O:$O, MAXIFS('単価履歴'!$O:$O,'単価履歴'!$E:$E,R$1,'単価履歴'!$F:$F,$A11))) | S11: =IF(MAXIFS('単価履歴'!$H:$H,'単価履歴'!$E:$E,S$1,'単価履歴'!$F:$F,$A11,'単価履歴'!$O:$O, MAXIFS('単価履歴'!$O:$O,'単価履歴'!$E:$E,S$1,'単価履歴'!$F:$F,$A11))=0,"", MAXIFS('単価履歴'!$H:$H,'単価履歴'!$E:$E,S$1,'単価履歴'!$F:$F,$A11,'単価履歴'!$O:$O, MAXIFS('単価履歴'!$O:$O,'単価履歴'!$E:$E,S$1,'単価履歴'!$F:$F,$A11))) | T11: =IF(MAXIFS('単価履歴'!$H:$H,'単価履歴'!$E:$E,T$1,'単価履歴'!$F:$F,$A11,'単価履歴'!$O:$O, MAXIFS('単価履歴'!$O:$O,'単価履歴'!$E:$E,T$1,'単価履歴'!$F:$F,$A11))=0,"", MAXIFS('単価履歴'!$H:$H,'単価履歴'!$E:$E,T$1,'単価履歴'!$F:$F,$A11,'単価履歴'!$O:$O, MAXIFS('単価履歴'!$O:$O,'単価履歴'!$E:$E,T$1,'単価履歴'!$F:$F,$A11))) | U11: =IF(MAXIFS('単価履歴'!$H:$H,'単価履歴'!$E:$E,U$1,'単価履歴'!$F:$F,$A11,'単価履歴'!$O:$O, MAXIFS('単価履歴'!$O:$O,'単価履歴'!$E:$E,U$1,'単価履歴'!$F:$F,$A11))=0,"", MAXIFS('単価履歴'!$H:$H,'単価履歴'!$E:$E,U$1,'単価履歴'!$F:$F,$A11,'単価履歴'!$O:$O, MAXIFS('単価履歴'!$O:$O,'単価履歴'!$E:$E,U$1,'単価履歴'!$F:$F,$A11))) -> 58.8 | V11: =IF(MAXIFS('単価履歴'!$H:$H,'単価履歴'!$E:$E,V$1,'単価履歴'!$F:$F,$A11,'単価履歴'!$O:$O, MAXIFS('単価履歴'!$O:$O,'単価履歴'!$E:$E,V$1,'単価履歴'!$F:$F,$A11))=0,"", MAXIFS('単価履歴'!$H:$H,'単価履歴'!$E:$E,V$1,'単価履歴'!$F:$F,$A11,'単価履歴'!$O:$O, MAXIFS('単価履歴'!$O:$O,'単価履歴'!$E:$E,V$1,'単価履歴'!$F:$F,$A11))) | ... Y11: =IF(MAXIFS('単価履歴'!$H:$H,'単価履歴'!$E:$E,Y$1,'単価履歴'!$F:$F,$A11,'単価履歴'!$O:$O, MAXIFS('単価履歴'!$O:$O,'単価履歴'!$E:$E,Y$1,'単価履歴'!$F:$F,$A11))=0,"", MAXIFS('単価履歴'!$H:$H,'単価履歴'!$E:$E,Y$1,'単価履歴'!$F:$F,$A11,'単価履歴'!$O:$O, MAXIFS('単価履歴'!$O:$O,'単価履歴'!$E:$E,Y$1,'単価履歴'!$F:$F,$A11))) -> 48.5 | AA11: =IF(MAXIFS('単価履歴'!$H:$H,'単価履歴'!$E:$E,AA$1,'単価履歴'!$F:$F,$A11,'単価履歴'!$O:$O, MAXIFS('単価履歴'!$O:$O,'単価履歴'!$E:$E,AA$1,'単価履歴'!$F:$F,$A11))=0,"", MAXIFS('単価履歴'!$H:$H,'単価履歴'!$E:$E,AA$1,'単価履歴'!$F:$F,$A11,'単価履歴'!$O:$O, MAXIFS('単価履歴'!$O:$O,'単価履歴'!$E:$E,AA$1,'単価履歴'!$F:$F,$A11))) -> 53 | AB11: =IF(MAXIFS('単価履歴'!$H:$H,'単価履歴'!$E:$E,AB$1,'単価履歴'!$F:$F,$A11,'単価履歴'!$O:$O, MAXIFS('単価履歴'!$O:$O,'単価履歴'!$E:$E,AB$1,'単価履歴'!$F:$F,$A11))=0,"", MAXIFS('単価履歴'!$H:$H,'単価履歴'!$E:$E,AB$1,'単価履歴'!$F:$F,$A11,'単価履歴'!$O:$O, MAXIFS('単価履歴'!$O:$O,'単価履歴'!$E:$E,AB$1,'単価履歴'!$F:$F,$A11))) | AC11: =IF(MAXIFS('単価履歴'!$H:$H,'単価履歴'!$E:$E,AC$1,'単価履歴'!$F:$F,$A11,'単価履歴'!$O:$O, MAXIFS('単価履歴'!$O:$O,'単価履歴'!$E:$E,AC$1,'単価履歴'!$F:$F,$A11))=0,"", MAXIFS('単価履歴'!$H:$H,'単価履歴'!$E:$E,AC$1,'単価履歴'!$F:$F,$A11,'単価履歴'!$O:$O, MAXIFS('単価履歴'!$O:$O,'単価履歴'!$E:$E,AC$1,'単価履歴'!$F:$F,$A11))) | AD11: =IF(MAXIFS('単価履歴'!$H:$H,'単価履歴'!$E:$E,AD$1,'単価履歴'!$F:$F,$A11,'単価履歴'!$O:$O, MAXIFS('単価履歴'!$O:$O,'単価履歴'!$E:$E,AD$1,'単価履歴'!$F:$F,$A11))=0,"", MAXIFS('単価履歴'!$H:$H,'単価履歴'!$E:$E,AD$1,'単価履歴'!$F:$F,$A11,'単価履歴'!$O:$O, MAXIFS('単価履歴'!$O:$O,'単価履歴'!$E:$E,AD$1,'単価履歴'!$F:$F,$A11))) | AE11: =IF(MAXIFS('単価履歴'!$H:$H,'単価履歴'!$E:$E,AE$1,'単価履歴'!$F:$F,$A11,'単価履歴'!$O:$O, MAXIFS('単価履歴'!$O:$O,'単価履歴'!$E:$E,AE$1,'単価履歴'!$F:$F,$A11))=0,"", MAXIFS('単価履歴'!$H:$H,'単価履歴'!$E:$E,AE$1,'単価履歴'!$F:$F,$A11,'単価履歴'!$O:$O, MAXIFS('単価履歴'!$O:$O,'単価履歴'!$E:$E,AE$1,'単価履歴'!$F:$F,$A11))) -> 47 | AF11: =IF(MAXIFS('単価履歴'!$H:$H,'単価履歴'!$E:$E,AF$1,'単価履歴'!$F:$F,$A11,'単価履歴'!$O:$O, MAXIFS('単価履歴'!$O:$O,'単価履歴'!$E:$E,AF$1,'単価履歴'!$F:$F,$A11))=0,"", MAXIFS('単価履歴'!$H:$H,'単価履歴'!$E:$E,AF$1,'単価履歴'!$F:$F,$A11,'単価履歴'!$O:$O, MAXIFS('単価履歴'!$O:$O,'単価履歴'!$E:$E,AF$1,'単価履歴'!$F:$F,$A11))) -> 45 | AG11: =IF(MAXIFS('単価履歴'!$H:$H,'単価履歴'!$E:$E,AG$1,'単価履歴'!$F:$F,$A11,'単価履歴'!$O:$O, MAXIFS('単価履歴'!$O:$O,'単価履歴'!$E:$E,AG$1,'単価履歴'!$F:$F,$A11))=0,"", MAXIFS('単価履歴'!$H:$H,'単価履歴'!$E:$E,AG$1,'単価履歴'!$F:$F,$A11,'単価履歴'!$O:$O, MAXIFS('単価履歴'!$O:$O,'単価履歴'!$E:$E,AG$1,'単価履歴'!$F:$F,$A11))) | AH11: =IF(MAXIFS('単価履歴'!$H:$H,'単価履歴'!$E:$E,AH$1,'単価履歴'!$F:$F,$A11,'単価履歴'!$O:$O, MAXIFS('単価履歴'!$O:$O,'単価履歴'!$E:$E,AH$1,'単価履歴'!$F:$F,$A11))=0,"", MAXIFS('単価履歴'!$H:$H,'単価履歴'!$E:$E,AH$1,'単価履歴'!$F:$F,$A11,'単価履歴'!$O:$O, MAXIFS('単価履歴'!$O:$O,'単価履歴'!$E:$E,AH$1,'単価履歴'!$F:$F,$A11))) | ... BY11: =IF(MAXIFS('単価履歴'!$H:$H,'単価履歴'!$E:$E,BY$1,'単価履歴'!$F:$F,$A11,'単価履歴'!$O:$O, MAXIFS('単価履歴'!$O:$O,'単価履歴'!$E:$E,BY$1,'単価履歴'!$F:$F,$A11))=0,"", MAXIFS('単価履歴'!$H:$H,'単価履歴'!$E:$E,BY$1,'単価履歴'!$F:$F,$A11,'単価履歴'!$O:$O, MAXIFS('単価履歴'!$O:$O,'単価履歴'!$E:$E,BY$1,'単価履歴'!$F:$F,$A11)))
A12: ＨＳ２ | C12: =IF(MAXIFS('単価履歴'!$H:$H,'単価履歴'!$E:$E,C$1,'単価履歴'!$F:$F,$A12,'単価履歴'!$O:$O, MAXIFS('単価履歴'!$O:$O,'単価履歴'!$E:$E,C$1,'単価履歴'!$F:$F,$A12))=0,"", MAXIFS('単価履歴'!$H:$H,'単価履歴'!$E:$E,C$1,'単価履歴'!$F:$F,$A12,'単価履歴'!$O:$O, MAXIFS('単価履歴'!$O:$O,'単価履歴'!$E:$E,C$1,'単価履歴'!$F:$F,$A12))) -> 57.4 | D12: =IF(MAXIFS('単価履歴'!$H:$H,'単価履歴'!$E:$E,D$1,'単価履歴'!$F:$F,$A12,'単価履歴'!$O:$O, MAXIFS('単価履歴'!$O:$O,'単価履歴'!$E:$E,D$1,'単価履歴'!$F:$F,$A12))=0,"", MAXIFS('単価履歴'!$H:$H,'単価履歴'!$E:$E,D$1,'単価履歴'!$F:$F,$A12,'単価履歴'!$O:$O, MAXIFS('単価履歴'!$O:$O,'単価履歴'!$E:$E,D$1,'単価履歴'!$F:$F,$A12))) -> 57.3 | H12: =IF(MAXIFS('単価履歴'!$H:$H,'単価履歴'!$E:$E,H$1,'単価履歴'!$F:$F,$A12,'単価履歴'!$O:$O, MAXIFS('単価履歴'!$O:$O,'単価履歴'!$E:$E,H$1,'単価履歴'!$F:$F,$A12))=0,"", MAXIFS('単価履歴'!$H:$H,'単価履歴'!$E:$E,H$1,'単価履歴'!$F:$F,$A12,'単価履歴'!$O:$O, MAXIFS('単価履歴'!$O:$O,'単価履歴'!$E:$E,H$1,'単価履歴'!$F:$F,$A12))) -> 55.3 | O12: =IF(MAXIFS('単価履歴'!$H:$H,'単価履歴'!$E:$E,O$1,'単価履歴'!$F:$F,$A12,'単価履歴'!$O:$O, MAXIFS('単価履歴'!$O:$O,'単価履歴'!$E:$E,O$1,'単価履歴'!$F:$F,$A12))=0,"", MAXIFS('単価履歴'!$H:$H,'単価履歴'!$E:$E,O$1,'単価履歴'!$F:$F,$A12,'単価履歴'!$O:$O, MAXIFS('単価履歴'!$O:$O,'単価履歴'!$E:$E,O$1,'単価履歴'!$F:$F,$A12))) | P12: =IF(MAXIFS('単価履歴'!$H:$H,'単価履歴'!$E:$E,P$1,'単価履歴'!$F:$F,$A12,'単価履歴'!$O:$O, MAXIFS('単価履歴'!$O:$O,'単価履歴'!$E:$E,P$1,'単価履歴'!$F:$F,$A12))=0,"", MAXIFS('単価履歴'!$H:$H,'単価履歴'!$E:$E,P$1,'単価履歴'!$F:$F,$A12,'単価履歴'!$O:$O, MAXIFS('単価履歴'!$O:$O,'単価履歴'!$E:$E,P$1,'単価履歴'!$F:$F,$A12))) | Q12: =IF(MAXIFS('単価履歴'!$H:$H,'単価履歴'!$E:$E,Q$1,'単価履歴'!$F:$F,$A12,'単価履歴'!$O:$O, MAXIFS('単価履歴'!$O:$O,'単価履歴'!$E:$E,Q$1,'単価履歴'!$F:$F,$A12))=0,"", MAXIFS('単価履歴'!$H:$H,'単価履歴'!$E:$E,Q$1,'単価履歴'!$F:$F,$A12,'単価履歴'!$O:$O, MAXIFS('単価履歴'!$O:$O,'単価履歴'!$E:$E,Q$1,'単価履歴'!$F:$F,$A12))) | R12: =IF(MAXIFS('単価履歴'!$H:$H,'単価履歴'!$E:$E,R$1,'単価履歴'!$F:$F,$A12,'単価履歴'!$O:$O, MAXIFS('単価履歴'!$O:$O,'単価履歴'!$E:$E,R$1,'単価履歴'!$F:$F,$A12))=0,"", MAXIFS('単価履歴'!$H:$H,'単価履歴'!$E:$E,R$1,'単価履歴'!$F:$F,$A12,'単価履歴'!$O:$O, MAXIFS('単価履歴'!$O:$O,'単価履歴'!$E:$E,R$1,'単価履歴'!$F:$F,$A12))) | S12: =IF(MAXIFS('単価履歴'!$H:$H,'単価履歴'!$E:$E,S$1,'単価履歴'!$F:$F,$A12,'単価履歴'!$O:$O, MAXIFS('単価履歴'!$O:$O,'単価履歴'!$E:$E,S$1,'単価履歴'!$F:$F,$A12))=0,"", MAXIFS('単価履歴'!$H:$H,'単価履歴'!$E:$E,S$1,'単価履歴'!$F:$F,$A12,'単価履歴'!$O:$O, MAXIFS('単価履歴'!$O:$O,'単価履歴'!$E:$E,S$1,'単価履歴'!$F:$F,$A12))) | T12: =IF(MAXIFS('単価履歴'!$H:$H,'単価履歴'!$E:$E,T$1,'単価履歴'!$F:$F,$A12,'単価履歴'!$O:$O, MAXIFS('単価履歴'!$O:$O,'単価履歴'!$E:$E,T$1,'単価履歴'!$F:$F,$A12))=0,"", MAXIFS('単価履歴'!$H:$H,'単価履歴'!$E:$E,T$1,'単価履歴'!$F:$F,$A12,'単価履歴'!$O:$O, MAXIFS('単価履歴'!$O:$O,'単価履歴'!$E:$E,T$1,'単価履歴'!$F:$F,$A12))) | U12: =IF(MAXIFS('単価履歴'!$H:$H,'単価履歴'!$E:$E,U$1,'単価履歴'!$F:$F,$A12,'単価履歴'!$O:$O, MAXIFS('単価履歴'!$O:$O,'単価履歴'!$E:$E,U$1,'単価履歴'!$F:$F,$A12))=0,"", MAXIFS('単価履歴'!$H:$H,'単価履歴'!$E:$E,U$1,'単価履歴'!$F:$F,$A12,'単価履歴'!$O:$O, MAXIFS('単価履歴'!$O:$O,'単価履歴'!$E:$E,U$1,'単価履歴'!$F:$F,$A12))) -> 58.5 | V12: =IF(MAXIFS('単価履歴'!$H:$H,'単価履歴'!$E:$E,V$1,'単価履歴'!$F:$F,$A12,'単価履歴'!$O:$O, MAXIFS('単価履歴'!$O:$O,'単価履歴'!$E:$E,V$1,'単価履歴'!$F:$F,$A12))=0,"", MAXIFS('単価履歴'!$H:$H,'単価履歴'!$E:$E,V$1,'単価履歴'!$F:$F,$A12,'単価履歴'!$O:$O, MAXIFS('単価履歴'!$O:$O,'単価履歴'!$E:$E,V$1,'単価履歴'!$F:$F,$A12))) | ... BY12: =IF(MAXIFS('単価履歴'!$H:$H,'単価履歴'!$E:$E,BY$1,'単価履歴'!$F:$F,$A12,'単価履歴'!$O:$O, MAXIFS('単価履歴'!$O:$O,'単価履歴'!$E:$E,BY$1,'単価履歴'!$F:$F,$A12))=0,"", MAXIFS('単価履歴'!$H:$H,'単価履歴'!$E:$E,BY$1,'単価履歴'!$F:$F,$A12,'単価履歴'!$O:$O, MAXIFS('単価履歴'!$O:$O,'単価履歴'!$E:$E,BY$1,'単価履歴'!$F:$F,$A12)))
A13: ＨＳ３ | D13: =IF(MAXIFS('単価履歴'!$H:$H,'単価履歴'!$E:$E,D$1,'単価履歴'!$F:$F,$A13,'単価履歴'!$O:$O, MAXIFS('単価履歴'!$O:$O,'単価履歴'!$E:$E,D$1,'単価履歴'!$F:$F,$A13))=0,"", MAXIFS('単価履歴'!$H:$H,'単価履歴'!$E:$E,D$1,'単価履歴'!$F:$F,$A13,'単価履歴'!$O:$O, MAXIFS('単価履歴'!$O:$O,'単価履歴'!$E:$E,D$1,'単価履歴'!$F:$F,$A13))) | O13: =IF(MAXIFS('単価履歴'!$H:$H,'単価履歴'!$E:$E,O$1,'単価履歴'!$F:$F,$A13,'単価履歴'!$O:$O, MAXIFS('単価履歴'!$O:$O,'単価履歴'!$E:$E,O$1,'単価履歴'!$F:$F,$A13))=0,"", MAXIFS('単価履歴'!$H:$H,'単価履歴'!$E:$E,O$1,'単価履歴'!$F:$F,$A13,'単価履歴'!$O:$O, MAXIFS('単価履歴'!$O:$O,'単価履歴'!$E:$E,O$1,'単価履歴'!$F:$F,$A13))) | P13: =IF(MAXIFS('単価履歴'!$H:$H,'単価履歴'!$E:$E,P$1,'単価履歴'!$F:$F,$A13,'単価履歴'!$O:$O, MAXIFS('単価履歴'!$O:$O,'単価履歴'!$E:$E,P$1,'単価履歴'!$F:$F,$A13))=0,"", MAXIFS('単価履歴'!$H:$H,'単価履歴'!$E:$E,P$1,'単価履歴'!$F:$F,$A13,'単価履歴'!$O:$O, MAXIFS('単価履歴'!$O:$O,'単価履歴'!$E:$E,P$1,'単価履歴'!$F:$F,$A13))) | Q13: =IF(MAXIFS('単価履歴'!$H:$H,'単価履歴'!$E:$E,Q$1,'単価履歴'!$F:$F,$A13,'単価履歴'!$O:$O, MAXIFS('単価履歴'!$O:$O,'単価履歴'!$E:$E,Q$1,'単価履歴'!$F:$F,$A13))=0,"", MAXIFS('単価履歴'!$H:$H,'単価履歴'!$E:$E,Q$1,'単価履歴'!$F:$F,$A13,'単価履歴'!$O:$O, MAXIFS('単価履歴'!$O:$O,'単価履歴'!$E:$E,Q$1,'単価履歴'!$F:$F,$A13))) | R13: =IF(MAXIFS('単価履歴'!$H:$H,'単価履歴'!$E:$E,R$1,'単価履歴'!$F:$F,$A13,'単価履歴'!$O:$O, MAXIFS('単価履歴'!$O:$O,'単価履歴'!$E:$E,R$1,'単価履歴'!$F:$F,$A13))=0,"", MAXIFS('単価履歴'!$H:$H,'単価履歴'!$E:$E,R$1,'単価履歴'!$F:$F,$A13,'単価履歴'!$O:$O, MAXIFS('単価履歴'!$O:$O,'単価履歴'!$E:$E,R$1,'単価履歴'!$F:$F,$A13))) | S13: =IF(MAXIFS('単価履歴'!$H:$H,'単価履歴'!$E:$E,S$1,'単価履歴'!$F:$F,$A13,'単価履歴'!$O:$O, MAXIFS('単価履歴'!$O:$O,'単価履歴'!$E:$E,S$1,'単価履歴'!$F:$F,$A13))=0,"", MAXIFS('単価履歴'!$H:$H,'単価履歴'!$E:$E,S$1,'単価履歴'!$F:$F,$A13,'単価履歴'!$O:$O, MAXIFS('単価履歴'!$O:$O,'単価履歴'!$E:$E,S$1,'単価履歴'!$F:$F,$A13))) | T13: =IF(MAXIFS('単価履歴'!$H:$H,'単価履歴'!$E:$E,T$1,'単価履歴'!$F:$F,$A13,'単価履歴'!$O:$O, MAXIFS('単価履歴'!$O:$O,'単価履歴'!$E:$E,T$1,'単価履歴'!$F:$F,$A13))=0,"", MAXIFS('単価履歴'!$H:$H,'単価履歴'!$E:$E,T$1,'単価履歴'!$F:$F,$A13,'単価履歴'!$O:$O, MAXIFS('単価履歴'!$O:$O,'単価履歴'!$E:$E,T$1,'単価履歴'!$F:$F,$A13))) | U13: =IF(MAXIFS('単価履歴'!$H:$H,'単価履歴'!$E:$E,U$1,'単価履歴'!$F:$F,$A13,'単価履歴'!$O:$O, MAXIFS('単価履歴'!$O:$O,'単価履歴'!$E:$E,U$1,'単価履歴'!$F:$F,$A13))=0,"", MAXIFS('単価履歴'!$H:$H,'単価履歴'!$E:$E,U$1,'単価履歴'!$F:$F,$A13,'単価履歴'!$O:$O, MAXIFS('単価履歴'!$O:$O,'単価履歴'!$E:$E,U$1,'単価履歴'!$F:$F,$A13))) -> 57.6 | V13: =IF(MAXIFS('単価履歴'!$H:$H,'単価履歴'!$E:$E,V$1,'単価履歴'!$F:$F,$A13,'単価履歴'!$O:$O, MAXIFS('単価履歴'!$O:$O,'単価履歴'!$E:$E,V$1,'単価履歴'!$F:$F,$A13))=0,"", MAXIFS('単価履歴'!$H:$H,'単価履歴'!$E:$E,V$1,'単価履歴'!$F:$F,$A13,'単価履歴'!$O:$O, MAXIFS('単価履歴'!$O:$O,'単価履歴'!$E:$E,V$1,'単価履歴'!$F:$F,$A13))) | ... BY13: =IF(MAXIFS('単価履歴'!$H:$H,'単価履歴'!$E:$E,BY$1,'単価履歴'!$F:$F,$A13,'単価履歴'!$O:$O, MAXIFS('単価履歴'!$O:$O,'単価履歴'!$E:$E,BY$1,'単価履歴'!$F:$F,$A13))=0,"", MAXIFS('単価履歴'!$H:$H,'単価履歴'!$E:$E,BY$1,'単価履歴'!$F:$F,$A13,'単価履歴'!$O:$O, MAXIFS('単価履歴'!$O:$O,'単価履歴'!$E:$E,BY$1,'単価履歴'!$F:$F,$A13)))
A14: Ｈ１(特A) | B14: =IF(MAXIFS('単価履歴'!$H:$H,'単価履歴'!$E:$E,B$1,'単価履歴'!$F:$F,$A14,'単価履歴'!$O:$O, MAXIFS('単価履歴'!$O:$O,'単価履歴'!$E:$E,B$1,'単価履歴'!$F:$F,$A14))=0,"", MAXIFS('単価履歴'!$H:$H,'単価履歴'!$E:$E,B$1,'単価履歴'!$F:$F,$A14,'単価履歴'!$O:$O, MAXIFS('単価履歴'!$O:$O,'単価履歴'!$E:$E,B$1,'単価履歴'!$F:$F,$A14))) -> 55 | C14: =IF(MAXIFS('単価履歴'!$H:$H,'単価履歴'!$E:$E,C$1,'単価履歴'!$F:$F,$A14,'単価履歴'!$O:$O, MAXIFS('単価履歴'!$O:$O,'単価履歴'!$E:$E,C$1,'単価履歴'!$F:$F,$A14))=0,"", MAXIFS('単価履歴'!$H:$H,'単価履歴'!$E:$E,C$1,'単価履歴'!$F:$F,$A14,'単価履歴'!$O:$O, MAXIFS('単価履歴'!$O:$O,'単価履歴'!$E:$E,C$1,'単価履歴'!$F:$F,$A14))) -> 55.3 | D14: =IF(MAXIFS('単価履歴'!$H:$H,'単価履歴'!$E:$E,D$1,'単価履歴'!$F:$F,$A14,'単価履歴'!$O:$O, MAXIFS('単価履歴'!$O:$O,'単価履歴'!$E:$E,D$1,'単価履歴'!$F:$F,$A14))=0,"", MAXIFS('単価履歴'!$H:$H,'単価履歴'!$E:$E,D$1,'単価履歴'!$F:$F,$A14,'単価履歴'!$O:$O, MAXIFS('単価履歴'!$O:$O,'単価履歴'!$E:$E,D$1,'単価履歴'!$F:$F,$A14))) -> 55.3 | G14: =IF(MAXIFS('単価履歴'!$H:$H,'単価履歴'!$E:$E,G$1,'単価履歴'!$F:$F,$A14,'単価履歴'!$O:$O, MAXIFS('単価履歴'!$O:$O,'単価履歴'!$E:$E,G$1,'単価履歴'!$F:$F,$A14))=0,"", MAXIFS('単価履歴'!$H:$H,'単価履歴'!$E:$E,G$1,'単価履歴'!$F:$F,$A14,'単価履歴'!$O:$O, MAXIFS('単価履歴'!$O:$O,'単価履歴'!$E:$E,G$1,'単価履歴'!$F:$F,$A14))) -> 55.5 | H14: =IF(MAXIFS('単価履歴'!$H:$H,'単価履歴'!$E:$E,H$1,'単価履歴'!$F:$F,$A14,'単価履歴'!$O:$O, MAXIFS('単価履歴'!$O:$O,'単価履歴'!$E:$E,H$1,'単価履歴'!$F:$F,$A14))=0,"", MAXIFS('単価履歴'!$H:$H,'単価履歴'!$E:$E,H$1,'単価履歴'!$F:$F,$A14,'単価履歴'!$O:$O, MAXIFS('単価履歴'!$O:$O,'単価履歴'!$E:$E,H$1,'単価履歴'!$F:$F,$A14))) -> 55.8 | K14: =IF(MAXIFS('単価履歴'!$H:$H,'単価履歴'!$E:$E,K$1,'単価履歴'!$F:$F,$A14,'単価履歴'!$O:$O, MAXIFS('単価履歴'!$O:$O,'単価履歴'!$E:$E,K$1,'単価履歴'!$F:$F,$A14))=0,"", MAXIFS('単価履歴'!$H:$H,'単価履歴'!$E:$E,K$1,'単価履歴'!$F:$F,$A14,'単価履歴'!$O:$O, MAXIFS('単価履歴'!$O:$O,'単価履歴'!$E:$E,K$1,'単価履歴'!$F:$F,$A14))) -> 54 | L14: =IF(MAXIFS('単価履歴'!$H:$H,'単価履歴'!$E:$E,L$1,'単価履歴'!$F:$F,$A14,'単価履歴'!$O:$O, MAXIFS('単価履歴'!$O:$O,'単価履歴'!$E:$E,L$1,'単価履歴'!$F:$F,$A14))=0,"", MAXIFS('単価履歴'!$H:$H,'単価履歴'!$E:$E,L$1,'単価履歴'!$F:$F,$A14,'単価履歴'!$O:$O, MAXIFS('単価履歴'!$O:$O,'単価履歴'!$E:$E,L$1,'単価履歴'!$F:$F,$A14))) -> 39.4 | M14: =IF(MAXIFS('単価履歴'!$H:$H,'単価履歴'!$E:$E,M$1,'単価履歴'!$F:$F,$A14,'単価履歴'!$O:$O, MAXIFS('単価履歴'!$O:$O,'単価履歴'!$E:$E,M$1,'単価履歴'!$F:$F,$A14))=0,"", MAXIFS('単価履歴'!$H:$H,'単価履歴'!$E:$E,M$1,'単価履歴'!$F:$F,$A14,'単価履歴'!$O:$O, MAXIFS('単価履歴'!$O:$O,'単価履歴'!$E:$E,M$1,'単価履歴'!$F:$F,$A14))) -> 56.2 | N14: =IF(MAXIFS('単価履歴'!$H:$H,'単価履歴'!$E:$E,N$1,'単価履歴'!$F:$F,$A14,'単価履歴'!$O:$O, MAXIFS('単価履歴'!$O:$O,'単価履歴'!$E:$E,N$1,'単価履歴'!$F:$F,$A14))=0,"", MAXIFS('単価履歴'!$H:$H,'単価履歴'!$E:$E,N$1,'単価履歴'!$F:$F,$A14,'単価履歴'!$O:$O, MAXIFS('単価履歴'!$O:$O,'単価履歴'!$E:$E,N$1,'単価履歴'!$F:$F,$A14))) -> 38.3 | O14: =IF(MAXIFS('単価履歴'!$H:$H,'単価履歴'!$E:$E,O$1,'単価履歴'!$F:$F,$A14,'単価履歴'!$O:$O, MAXIFS('単価履歴'!$O:$O,'単価履歴'!$E:$E,O$1,'単価履歴'!$F:$F,$A14))=0,"", MAXIFS('単価履歴'!$H:$H,'単価履歴'!$E:$E,O$1,'単価履歴'!$F:$F,$A14,'単価履歴'!$O:$O, MAXIFS('単価履歴'!$O:$O,'単価履歴'!$E:$E,O$1,'単価履歴'!$F:$F,$A14))) | P14: =IF(MAXIFS('単価履歴'!$H:$H,'単価履歴'!$E:$E,P$1,'単価履歴'!$F:$F,$A14,'単価履歴'!$O:$O, MAXIFS('単価履歴'!$O:$O,'単価履歴'!$E:$E,P$1,'単価履歴'!$F:$F,$A14))=0,"", MAXIFS('単価履歴'!$H:$H,'単価履歴'!$E:$E,P$1,'単価履歴'!$F:$F,$A14,'単価履歴'!$O:$O, MAXIFS('単価履歴'!$O:$O,'単価履歴'!$E:$E,P$1,'単価履歴'!$F:$F,$A14))) -> 58.5 | Q14: =IF(MAXIFS('単価履歴'!$H:$H,'単価履歴'!$E:$E,Q$1,'単価履歴'!$F:$F,$A14,'単価履歴'!$O:$O, MAXIFS('単価履歴'!$O:$O,'単価履歴'!$E:$E,Q$1,'単価履歴'!$F:$F,$A14))=0,"", MAXIFS('単価履歴'!$H:$H,'単価履歴'!$E:$E,Q$1,'単価履歴'!$F:$F,$A14,'単価履歴'!$O:$O, MAXIFS('単価履歴'!$O:$O,'単価履歴'!$E:$E,Q$1,'単価履歴'!$F:$F,$A14))) | R14: =IF(MAXIFS('単価履歴'!$H:$H,'単価履歴'!$E:$E,R$1,'単価履歴'!$F:$F,$A14,'単価履歴'!$O:$O, MAXIFS('単価履歴'!$O:$O,'単価履歴'!$E:$E,R$1,'単価履歴'!$F:$F,$A14))=0,"", MAXIFS('単価履歴'!$H:$H,'単価履歴'!$E:$E,R$1,'単価履歴'!$F:$F,$A14,'単価履歴'!$O:$O, MAXIFS('単価履歴'!$O:$O,'単価履歴'!$E:$E,R$1,'単価履歴'!$F:$F,$A14))) -> 58.2 | ... BY14: =IF(MAXIFS('単価履歴'!$H:$H,'単価履歴'!$E:$E,BY$1,'単価履歴'!$F:$F,$A14,'単価履歴'!$O:$O, MAXIFS('単価履歴'!$O:$O,'単価履歴'!$E:$E,BY$1,'単価履歴'!$F:$F,$A14))=0,"", MAXIFS('単価履歴'!$H:$H,'単価履歴'!$E:$E,BY$1,'単価履歴'!$F:$F,$A14,'単価履歴'!$O:$O, MAXIFS('単価履歴'!$O:$O,'単価履歴'!$E:$E,BY$1,'単価履歴'!$F:$F,$A14)))
A15: ＪＨ１(H2T山口)鍛造ﾊﾞﾘ | D15: =IF(MAXIFS('単価履歴'!$H:$H,'単価履歴'!$E:$E,D$1,'単価履歴'!$F:$F,$A15,'単価履歴'!$O:$O, MAXIFS('単価履歴'!$O:$O,'単価履歴'!$E:$E,D$1,'単価履歴'!$F:$F,$A15))=0,"", MAXIFS('単価履歴'!$H:$H,'単価履歴'!$E:$E,D$1,'単価履歴'!$F:$F,$A15,'単価履歴'!$O:$O, MAXIFS('単価履歴'!$O:$O,'単価履歴'!$E:$E,D$1,'単価履歴'!$F:$F,$A15))) | G15: =IF(MAXIFS('単価履歴'!$H:$H,'単価履歴'!$E:$E,G$1,'単価履歴'!$F:$F,$A15,'単価履歴'!$O:$O, MAXIFS('単価履歴'!$O:$O,'単価履歴'!$E:$E,G$1,'単価履歴'!$F:$F,$A15))=0,"", MAXIFS('単価履歴'!$H:$H,'単価履歴'!$E:$E,G$1,'単価履歴'!$F:$F,$A15,'単価履歴'!$O:$O, MAXIFS('単価履歴'!$O:$O,'単価履歴'!$E:$E,G$1,'単価履歴'!$F:$F,$A15))) -> 52.7 | K15: =IF(MAXIFS('単価履歴'!$H:$H,'単価履歴'!$E:$E,K$1,'単価履歴'!$F:$F,$A15,'単価履歴'!$O:$O, MAXIFS('単価履歴'!$O:$O,'単価履歴'!$E:$E,K$1,'単価履歴'!$F:$F,$A15))=0,"", MAXIFS('単価履歴'!$H:$H,'単価履歴'!$E:$E,K$1,'単価履歴'!$F:$F,$A15,'単価履歴'!$O:$O, MAXIFS('単価履歴'!$O:$O,'単価履歴'!$E:$E,K$1,'単価履歴'!$F:$F,$A15))) -> 53 | L15: =IF(MAXIFS('単価履歴'!$H:$H,'単価履歴'!$E:$E,L$1,'単価履歴'!$F:$F,$A15,'単価履歴'!$O:$O, MAXIFS('単価履歴'!$O:$O,'単価履歴'!$E:$E,L$1,'単価履歴'!$F:$F,$A15))=0,"", MAXIFS('単価履歴'!$H:$H,'単価履歴'!$E:$E,L$1,'単価履歴'!$F:$F,$A15,'単価履歴'!$O:$O, MAXIFS('単価履歴'!$O:$O,'単価履歴'!$E:$E,L$1,'単価履歴'!$F:$F,$A15))) -> 38.4 | N15: =IF(MAXIFS('単価履歴'!$H:$H,'単価履歴'!$E:$E,N$1,'単価履歴'!$F:$F,$A15,'単価履歴'!$O:$O, MAXIFS('単価履歴'!$O:$O,'単価履歴'!$E:$E,N$1,'単価履歴'!$F:$F,$A15))=0,"", MAXIFS('単価履歴'!$H:$H,'単価履歴'!$E:$E,N$1,'単価履歴'!$F:$F,$A15,'単価履歴'!$O:$O, MAXIFS('単価履歴'!$O:$O,'単価履歴'!$E:$E,N$1,'単価履歴'!$F:$F,$A15))) -> 45.7 | O15: =IF(MAXIFS('単価履歴'!$H:$H,'単価履歴'!$E:$E,O$1,'単価履歴'!$F:$F,$A15,'単価履歴'!$O:$O, MAXIFS('単価履歴'!$O:$O,'単価履歴'!$E:$E,O$1,'単価履歴'!$F:$F,$A15))=0,"", MAXIFS('単価履歴'!$H:$H,'単価履歴'!$E:$E,O$1,'単価履歴'!$F:$F,$A15,'単価履歴'!$O:$O, MAXIFS('単価履歴'!$O:$O,'単価履歴'!$E:$E,O$1,'単価履歴'!$F:$F,$A15))) | P15: =IF(MAXIFS('単価履歴'!$H:$H,'単価履歴'!$E:$E,P$1,'単価履歴'!$F:$F,$A15,'単価履歴'!$O:$O, MAXIFS('単価履歴'!$O:$O,'単価履歴'!$E:$E,P$1,'単価履歴'!$F:$F,$A15))=0,"", MAXIFS('単価履歴'!$H:$H,'単価履歴'!$E:$E,P$1,'単価履歴'!$F:$F,$A15,'単価履歴'!$O:$O, MAXIFS('単価履歴'!$O:$O,'単価履歴'!$E:$E,P$1,'単価履歴'!$F:$F,$A15))) | Q15: =IF(MAXIFS('単価履歴'!$H:$H,'単価履歴'!$E:$E,Q$1,'単価履歴'!$F:$F,$A15,'単価履歴'!$O:$O, MAXIFS('単価履歴'!$O:$O,'単価履歴'!$E:$E,Q$1,'単価履歴'!$F:$F,$A15))=0,"", MAXIFS('単価履歴'!$H:$H,'単価履歴'!$E:$E,Q$1,'単価履歴'!$F:$F,$A15,'単価履歴'!$O:$O, MAXIFS('単価履歴'!$O:$O,'単価履歴'!$E:$E,Q$1,'単価履歴'!$F:$F,$A15))) | R15: =IF(MAXIFS('単価履歴'!$H:$H,'単価履歴'!$E:$E,R$1,'単価履歴'!$F:$F,$A15,'単価履歴'!$O:$O, MAXIFS('単価履歴'!$O:$O,'単価履歴'!$E:$E,R$1,'単価履歴'!$F:$F,$A15))=0,"", MAXIFS('単価履歴'!$H:$H,'単価履歴'!$E:$E,R$1,'単価履歴'!$F:$F,$A15,'単価履歴'!$O:$O, MAXIFS('単価履歴'!$O:$O,'単価履歴'!$E:$E,R$1,'単価履歴'!$F:$F,$A15))) | S15: =IF(MAXIFS('単価履歴'!$H:$H,'単価履歴'!$E:$E,S$1,'単価履歴'!$F:$F,$A15,'単価履歴'!$O:$O, MAXIFS('単価履歴'!$O:$O,'単価履歴'!$E:$E,S$1,'単価履歴'!$F:$F,$A15))=0,"", MAXIFS('単価履歴'!$H:$H,'単価履歴'!$E:$E,S$1,'単価履歴'!$F:$F,$A15,'単価履歴'!$O:$O, MAXIFS('単価履歴'!$O:$O,'単価履歴'!$E:$E,S$1,'単価履歴'!$F:$F,$A15))) | T15: =IF(MAXIFS('単価履歴'!$H:$H,'単価履歴'!$E:$E,T$1,'単価履歴'!$F:$F,$A15,'単価履歴'!$O:$O, MAXIFS('単価履歴'!$O:$O,'単価履歴'!$E:$E,T$1,'単価履歴'!$F:$F,$A15))=0,"", MAXIFS('単価履歴'!$H:$H,'単価履歴'!$E:$E,T$1,'単価履歴'!$F:$F,$A15,'単価履歴'!$O:$O, MAXIFS('単価履歴'!$O:$O,'単価履歴'!$E:$E,T$1,'単価履歴'!$F:$F,$A15))) | U15: =IF(MAXIFS('単価履歴'!$H:$H,'単価履歴'!$E:$E,U$1,'単価履歴'!$F:$F,$A15,'単価履歴'!$O:$O, MAXIFS('単価履歴'!$O:$O,'単価履歴'!$E:$E,U$1,'単価履歴'!$F:$F,$A15))=0,"", MAXIFS('単価履歴'!$H:$H,'単価履歴'!$E:$E,U$1,'単価履歴'!$F:$F,$A15,'単価履歴'!$O:$O, MAXIFS('単価履歴'!$O:$O,'単価履歴'!$E:$E,U$1,'単価履歴'!$F:$F,$A15))) | ... BY15: =IF(MAXIFS('単価履歴'!$H:$H,'単価履歴'!$E:$E,BY$1,'単価履歴'!$F:$F,$A15,'単価履歴'!$O:$O, MAXIFS('単価履歴'!$O:$O,'単価履歴'!$E:$E,BY$1,'単価履歴'!$F:$F,$A15))=0,"", MAXIFS('単価履歴'!$H:$H,'単価履歴'!$E:$E,BY$1,'単価履歴'!$F:$F,$A15,'単価履歴'!$O:$O, MAXIFS('単価履歴'!$O:$O,'単価履歴'!$E:$E,BY$1,'単価履歴'!$F:$F,$A15)))
A16: Ｈ２(特級) | B16: =IF(MAXIFS('単価履歴'!$H:$H,'単価履歴'!$E:$E,B$1,'単価履歴'!$F:$F,$A16,'単価履歴'!$O:$O, MAXIFS('単価履歴'!$O:$O,'単価履歴'!$E:$E,B$1,'単価履歴'!$F:$F,$A16))=0,"", MAXIFS('単価履歴'!$H:$H,'単価履歴'!$E:$E,B$1,'単価履歴'!$F:$F,$A16,'単価履歴'!$O:$O, MAXIFS('単価履歴'!$O:$O,'単価履歴'!$E:$E,B$1,'単価履歴'!$F:$F,$A16))) -> 53 | C16: =IF(MAXIFS('単価履歴'!$H:$H,'単価履歴'!$E:$E,C$1,'単価履歴'!$F:$F,$A16,'単価履歴'!$O:$O, MAXIFS('単価履歴'!$O:$O,'単価履歴'!$E:$E,C$1,'単価履歴'!$F:$F,$A16))=0,"", MAXIFS('単価履歴'!$H:$H,'単価履歴'!$E:$E,C$1,'単価履歴'!$F:$F,$A16,'単価履歴'!$O:$O, MAXIFS('単価履歴'!$O:$O,'単価履歴'!$E:$E,C$1,'単価履歴'!$F:$F,$A16))) -> 52.5 | D16: =IF(MAXIFS('単価履歴'!$H:$H,'単価履歴'!$E:$E,D$1,'単価履歴'!$F:$F,$A16,'単価履歴'!$O:$O, MAXIFS('単価履歴'!$O:$O,'単価履歴'!$E:$E,D$1,'単価履歴'!$F:$F,$A16))=0,"", MAXIFS('単価履歴'!$H:$H,'単価履歴'!$E:$E,D$1,'単価履歴'!$F:$F,$A16,'単価履歴'!$O:$O, MAXIFS('単価履歴'!$O:$O,'単価履歴'!$E:$E,D$1,'単価履歴'!$F:$F,$A16))) -> 49.3 | G16: =IF(MAXIFS('単価履歴'!$H:$H,'単価履歴'!$E:$E,G$1,'単価履歴'!$F:$F,$A16,'単価履歴'!$O:$O, MAXIFS('単価履歴'!$O:$O,'単価履歴'!$E:$E,G$1,'単価履歴'!$F:$F,$A16))=0,"", MAXIFS('単価履歴'!$H:$H,'単価履歴'!$E:$E,G$1,'単価履歴'!$F:$F,$A16,'単価履歴'!$O:$O, MAXIFS('単価履歴'!$O:$O,'単価履歴'!$E:$E,G$1,'単価履歴'!$F:$F,$A16))) -> 54.5 | H16: =IF(MAXIFS('単価履歴'!$H:$H,'単価履歴'!$E:$E,H$1,'単価履歴'!$F:$F,$A16,'単価履歴'!$O:$O, MAXIFS('単価履歴'!$O:$O,'単価履歴'!$E:$E,H$1,'単価履歴'!$F:$F,$A16))=0,"", MAXIFS('単価履歴'!$H:$H,'単価履歴'!$E:$E,H$1,'単価履歴'!$F:$F,$A16,'単価履歴'!$O:$O, MAXIFS('単価履歴'!$O:$O,'単価履歴'!$E:$E,H$1,'単価履歴'!$F:$F,$A16))) -> 53.8 | K16: =IF(MAXIFS('単価履歴'!$H:$H,'単価履歴'!$E:$E,K$1,'単価履歴'!$F:$F,$A16,'単価履歴'!$O:$O, MAXIFS('単価履歴'!$O:$O,'単価履歴'!$E:$E,K$1,'単価履歴'!$F:$F,$A16))=0,"", MAXIFS('単価履歴'!$H:$H,'単価履歴'!$E:$E,K$1,'単価履歴'!$F:$F,$A16,'単価履歴'!$O:$O, MAXIFS('単価履歴'!$O:$O,'単価履歴'!$E:$E,K$1,'単価履歴'!$F:$F,$A16))) -> 51 | L16: =IF(MAXIFS('単価履歴'!$H:$H,'単価履歴'!$E:$E,L$1,'単価履歴'!$F:$F,$A16,'単価履歴'!$O:$O, MAXIFS('単価履歴'!$O:$O,'単価履歴'!$E:$E,L$1,'単価履歴'!$F:$F,$A16))=0,"", MAXIFS('単価履歴'!$H:$H,'単価履歴'!$E:$E,L$1,'単価履歴'!$F:$F,$A16,'単価履歴'!$O:$O, MAXIFS('単価履歴'!$O:$O,'単価履歴'!$E:$E,L$1,'単価履歴'!$F:$F,$A16))) -> 35.2 | M16: =IF(MAXIFS('単価履歴'!$H:$H,'単価履歴'!$E:$E,M$1,'単価履歴'!$F:$F,$A16,'単価履歴'!$O:$O, MAXIFS('単価履歴'!$O:$O,'単価履歴'!$E:$E,M$1,'単価履歴'!$F:$F,$A16))=0,"", MAXIFS('単価履歴'!$H:$H,'単価履歴'!$E:$E,M$1,'単価履歴'!$F:$F,$A16,'単価履歴'!$O:$O, MAXIFS('単価履歴'!$O:$O,'単価履歴'!$E:$E,M$1,'単価履歴'!$F:$F,$A16))) -> 53.7 | N16: =IF(MAXIFS('単価履歴'!$H:$H,'単価履歴'!$E:$E,N$1,'単価履歴'!$F:$F,$A16,'単価履歴'!$O:$O, MAXIFS('単価履歴'!$O:$O,'単価履歴'!$E:$E,N$1,'単価履歴'!$F:$F,$A16))=0,"", MAXIFS('単価履歴'!$H:$H,'単価履歴'!$E:$E,N$1,'単価履歴'!$F:$F,$A16,'単価履歴'!$O:$O, MAXIFS('単価履歴'!$O:$O,'単価履歴'!$E:$E,N$1,'単価履歴'!$F:$F,$A16))) -> 43.5 | O16: =IF(MAXIFS('単価履歴'!$H:$H,'単価履歴'!$E:$E,O$1,'単価履歴'!$F:$F,$A16,'単価履歴'!$O:$O, MAXIFS('単価履歴'!$O:$O,'単価履歴'!$E:$E,O$1,'単価履歴'!$F:$F,$A16))=0,"", MAXIFS('単価履歴'!$H:$H,'単価履歴'!$E:$E,O$1,'単価履歴'!$F:$F,$A16,'単価履歴'!$O:$O, MAXIFS('単価履歴'!$O:$O,'単価履歴'!$E:$E,O$1,'単価履歴'!$F:$F,$A16))) -> 53.7 | P16: =IF(MAXIFS('単価履歴'!$H:$H,'単価履歴'!$E:$E,P$1,'単価履歴'!$F:$F,$A16,'単価履歴'!$O:$O, MAXIFS('単価履歴'!$O:$O,'単価履歴'!$E:$E,P$1,'単価履歴'!$F:$F,$A16))=0,"", MAXIFS('単価履歴'!$H:$H,'単価履歴'!$E:$E,P$1,'単価履歴'!$F:$F,$A16,'単価履歴'!$O:$O, MAXIFS('単価履歴'!$O:$O,'単価履歴'!$E:$E,P$1,'単価履歴'!$F:$F,$A16))) -> 56.5 | Q16: =IF(MAXIFS('単価履歴'!$H:$H,'単価履歴'!$E:$E,Q$1,'単価履歴'!$F:$F,$A16,'単価履歴'!$O:$O, MAXIFS('単価履歴'!$O:$O,'単価履歴'!$E:$E,Q$1,'単価履歴'!$F:$F,$A16))=0,"", MAXIFS('単価履歴'!$H:$H,'単価履歴'!$E:$E,Q$1,'単価履歴'!$F:$F,$A16,'単価履歴'!$O:$O, MAXIFS('単価履歴'!$O:$O,'単価履歴'!$E:$E,Q$1,'単価履歴'!$F:$F,$A16))) | R16: =IF(MAXIFS('単価履歴'!$H:$H,'単価履歴'!$E:$E,R$1,'単価履歴'!$F:$F,$A16,'単価履歴'!$O:$O, MAXIFS('単価履歴'!$O:$O,'単価履歴'!$E:$E,R$1,'単価履歴'!$F:$F,$A16))=0,"", MAXIFS('単価履歴'!$H:$H,'単価履歴'!$E:$E,R$1,'単価履歴'!$F:$F,$A16,'単価履歴'!$O:$O, MAXIFS('単価履歴'!$O:$O,'単価履歴'!$E:$E,R$1,'単価履歴'!$F:$F,$A16))) -> 56.2 | ... BA16: =IF(MAXIFS('単価履歴'!$H:$H,'単価履歴'!$E:$E,BA$1,'単価履歴'!$F:$F,$A16,'単価履歴'!$O:$O, MAXIFS('単価履歴'!$O:$O,'単価履歴'!$E:$E,BA$1,'単価履歴'!$F:$F,$A16))=0,"", MAXIFS('単価履歴'!$H:$H,'単価履歴'!$E:$E,BA$1,'単価履歴'!$F:$F,$A16,'単価履歴'!$O:$O, MAXIFS('単価履歴'!$O:$O,'単価履歴'!$E:$E,BA$1,'単価履歴'!$F:$F,$A16))) -> 50.5 | BC16: =IF(MAXIFS('単価履歴'!$H:$H,'単価履歴'!$E:$E,BC$1,'単価履歴'!$F:$F,$A16,'単価履歴'!$O:$O, MAXIFS('単価履歴'!$O:$O,'単価履歴'!$E:$E,BC$1,'単価履歴'!$F:$F,$A16))=0,"", MAXIFS('単価履歴'!$H:$H,'単価履歴'!$E:$E,BC$1,'単価履歴'!$F:$F,$A16,'単価履歴'!$O:$O, MAXIFS('単価履歴'!$O:$O,'単価履歴'!$E:$E,BC$1,'単価履歴'!$F:$F,$A16))) -> 52.2 | BD16: =IF(MAXIFS('単価履歴'!$H:$H,'単価履歴'!$E:$E,BD$1,'単価履歴'!$F:$F,$A16,'単価履歴'!$O:$O, MAXIFS('単価履歴'!$O:$O,'単価履歴'!$E:$E,BD$1,'単価履歴'!$F:$F,$A16))=0,"", MAXIFS('単価履歴'!$H:$H,'単価履歴'!$E:$E,BD$1,'単価履歴'!$F:$F,$A16,'単価履歴'!$O:$O, MAXIFS('単価履歴'!$O:$O,'単価履歴'!$E:$E,BD$1,'単価履歴'!$F:$F,$A16))) -> 49.9 | BE16: =IF(MAXIFS('単価履歴'!$H:$H,'単価履歴'!$E:$E,BE$1,'単価履歴'!$F:$F,$A16,'単価履歴'!$O:$O, MAXIFS('単価履歴'!$O:$O,'単価履歴'!$E:$E,BE$1,'単価履歴'!$F:$F,$A16))=0,"", MAXIFS('単価履歴'!$H:$H,'単価履歴'!$E:$E,BE$1,'単価履歴'!$F:$F,$A16,'単価履歴'!$O:$O, MAXIFS('単価履歴'!$O:$O,'単価履歴'!$E:$E,BE$1,'単価履歴'!$F:$F,$A16))) -> 50.7 | BF16: =IF(MAXIFS('単価履歴'!$H:$H,'単価履歴'!$E:$E,BF$1,'単価履歴'!$F:$F,$A16,'単価履歴'!$O:$O, MAXIFS('単価履歴'!$O:$O,'単価履歴'!$E:$E,BF$1,'単価履歴'!$F:$F,$A16))=0,"", MAXIFS('単価履歴'!$H:$H,'単価履歴'!$E:$E,BF$1,'単価履歴'!$F:$F,$A16,'単価履歴'!$O:$O, MAXIFS('単価履歴'!$O:$O,'単価履歴'!$E:$E,BF$1,'単価履歴'!$F:$F,$A16))) | BG16: =IF(MAXIFS('単価履歴'!$H:$H,'単価履歴'!$E:$E,BG$1,'単価履歴'!$F:$F,$A16,'単価履歴'!$O:$O, MAXIFS('単価履歴'!$O:$O,'単価履歴'!$E:$E,BG$1,'単価履歴'!$F:$F,$A16))=0,"", MAXIFS('単価履歴'!$H:$H,'単価履歴'!$E:$E,BG$1,'単価履歴'!$F:$F,$A16,'単価履歴'!$O:$O, MAXIFS('単価履歴'!$O:$O,'単価履歴'!$E:$E,BG$1,'単価履歴'!$F:$F,$A16))) -> 47 | BH16: =IF(MAXIFS('単価履歴'!$H:$H,'単価履歴'!$E:$E,BH$1,'単価履歴'!$F:$F,$A16,'単価履歴'!$O:$O, MAXIFS('単価履歴'!$O:$O,'単価履歴'!$E:$E,BH$1,'単価履歴'!$F:$F,$A16))=0,"", MAXIFS('単価履歴'!$H:$H,'単価履歴'!$E:$E,BH$1,'単価履歴'!$F:$F,$A16,'単価履歴'!$O:$O, MAXIFS('単価履歴'!$O:$O,'単価履歴'!$E:$E,BH$1,'単価履歴'!$F:$F,$A16))) | BI16: =IF(MAXIFS('単価履歴'!$H:$H,'単価履歴'!$E:$E,BI$1,'単価履歴'!$F:$F,$A16,'単価履歴'!$O:$O, MAXIFS('単価履歴'!$O:$O,'単価履歴'!$E:$E,BI$1,'単価履歴'!$F:$F,$A16))=0,"", MAXIFS('単価履歴'!$H:$H,'単価履歴'!$E:$E,BI$1,'単価履歴'!$F:$F,$A16,'単価履歴'!$O:$O, MAXIFS('単価履歴'!$O:$O,'単価履歴'!$E:$E,BI$1,'単価履歴'!$F:$F,$A16))) | BJ16: =IF(MAXIFS('単価履歴'!$H:$H,'単価履歴'!$E:$E,BJ$1,'単価履歴'!$F:$F,$A16,'単価履歴'!$O:$O, MAXIFS('単価履歴'!$O:$O,'単価履歴'!$E:$E,BJ$1,'単価履歴'!$F:$F,$A16))=0,"", MAXIFS('単価履歴'!$H:$H,'単価履歴'!$E:$E,BJ$1,'単価履歴'!$F:$F,$A16,'単価履歴'!$O:$O, MAXIFS('単価履歴'!$O:$O,'単価履歴'!$E:$E,BJ$1,'単価履歴'!$F:$F,$A16))) | ... BY16: =IF(MAXIFS('単価履歴'!$H:$H,'単価履歴'!$E:$E,BY$1,'単価履歴'!$F:$F,$A16,'単価履歴'!$O:$O, MAXIFS('単価履歴'!$O:$O,'単価履歴'!$E:$E,BY$1,'単価履歴'!$F:$F,$A16))=0,"", MAXIFS('単価履歴'!$H:$H,'単価履歴'!$E:$E,BY$1,'単価履歴'!$F:$F,$A16,'単価履歴'!$O:$O, MAXIFS('単価履歴'!$O:$O,'単価履歴'!$E:$E,BY$1,'単価履歴'!$F:$F,$A16)))
A17: Ｈ３(1級) | B17: =IF(MAXIFS('単価履歴'!$H:$H,'単価履歴'!$E:$E,B$1,'単価履歴'!$F:$F,$A17,'単価履歴'!$O:$O, MAXIFS('単価履歴'!$O:$O,'単価履歴'!$E:$E,B$1,'単価履歴'!$F:$F,$A17))=0,"", MAXIFS('単価履歴'!$H:$H,'単価履歴'!$E:$E,B$1,'単価履歴'!$F:$F,$A17,'単価履歴'!$O:$O, MAXIFS('単価履歴'!$O:$O,'単価履歴'!$E:$E,B$1,'単価履歴'!$F:$F,$A17))) -> 53 | C17: =IF(MAXIFS('単価履歴'!$H:$H,'単価履歴'!$E:$E,C$1,'単価履歴'!$F:$F,$A17,'単価履歴'!$O:$O, MAXIFS('単価履歴'!$O:$O,'単価履歴'!$E:$E,C$1,'単価履歴'!$F:$F,$A17))=0,"", MAXIFS('単価履歴'!$H:$H,'単価履歴'!$E:$E,C$1,'単価履歴'!$F:$F,$A17,'単価履歴'!$O:$O, MAXIFS('単価履歴'!$O:$O,'単価履歴'!$E:$E,C$1,'単価履歴'!$F:$F,$A17))) -> 51.5 | D17: =IF(MAXIFS('単価履歴'!$H:$H,'単価履歴'!$E:$E,D$1,'単価履歴'!$F:$F,$A17,'単価履歴'!$O:$O, MAXIFS('単価履歴'!$O:$O,'単価履歴'!$E:$E,D$1,'単価履歴'!$F:$F,$A17))=0,"", MAXIFS('単価履歴'!$H:$H,'単価履歴'!$E:$E,D$1,'単価履歴'!$F:$F,$A17,'単価履歴'!$O:$O, MAXIFS('単価履歴'!$O:$O,'単価履歴'!$E:$E,D$1,'単価履歴'!$F:$F,$A17))) -> 45.3 | G17: =IF(MAXIFS('単価履歴'!$H:$H,'単価履歴'!$E:$E,G$1,'単価履歴'!$F:$F,$A17,'単価履歴'!$O:$O, MAXIFS('単価履歴'!$O:$O,'単価履歴'!$E:$E,G$1,'単価履歴'!$F:$F,$A17))=0,"", MAXIFS('単価履歴'!$H:$H,'単価履歴'!$E:$E,G$1,'単価履歴'!$F:$F,$A17,'単価履歴'!$O:$O, MAXIFS('単価履歴'!$O:$O,'単価履歴'!$E:$E,G$1,'単価履歴'!$F:$F,$A17))) -> 54 | H17: =IF(MAXIFS('単価履歴'!$H:$H,'単価履歴'!$E:$E,H$1,'単価履歴'!$F:$F,$A17,'単価履歴'!$O:$O, MAXIFS('単価履歴'!$O:$O,'単価履歴'!$E:$E,H$1,'単価履歴'!$F:$F,$A17))=0,"", MAXIFS('単価履歴'!$H:$H,'単価履歴'!$E:$E,H$1,'単価履歴'!$F:$F,$A17,'単価履歴'!$O:$O, MAXIFS('単価履歴'!$O:$O,'単価履歴'!$E:$E,H$1,'単価履歴'!$F:$F,$A17))) -> 53.3 | K17: =IF(MAXIFS('単価履歴'!$H:$H,'単価履歴'!$E:$E,K$1,'単価履歴'!$F:$F,$A17,'単価履歴'!$O:$O, MAXIFS('単価履歴'!$O:$O,'単価履歴'!$E:$E,K$1,'単価履歴'!$F:$F,$A17))=0,"", MAXIFS('単価履歴'!$H:$H,'単価履歴'!$E:$E,K$1,'単価履歴'!$F:$F,$A17,'単価履歴'!$O:$O, MAXIFS('単価履歴'!$O:$O,'単価履歴'!$E:$E,K$1,'単価履歴'!$F:$F,$A17))) -> 50.5 | L17: =IF(MAXIFS('単価履歴'!$H:$H,'単価履歴'!$E:$E,L$1,'単価履歴'!$F:$F,$A17,'単価履歴'!$O:$O, MAXIFS('単価履歴'!$O:$O,'単価履歴'!$E:$E,L$1,'単価履歴'!$F:$F,$A17))=0,"", MAXIFS('単価履歴'!$H:$H,'単価履歴'!$E:$E,L$1,'単価履歴'!$F:$F,$A17,'単価履歴'!$O:$O, MAXIFS('単価履歴'!$O:$O,'単価履歴'!$E:$E,L$1,'単価履歴'!$F:$F,$A17))) -> 34.2 | M17: =IF(MAXIFS('単価履歴'!$H:$H,'単価履歴'!$E:$E,M$1,'単価履歴'!$F:$F,$A17,'単価履歴'!$O:$O, MAXIFS('単価履歴'!$O:$O,'単価履歴'!$E:$E,M$1,'単価履歴'!$F:$F,$A17))=0,"", MAXIFS('単価履歴'!$H:$H,'単価履歴'!$E:$E,M$1,'単価履歴'!$F:$F,$A17,'単価履歴'!$O:$O, MAXIFS('単価履歴'!$O:$O,'単価履歴'!$E:$E,M$1,'単価履歴'!$F:$F,$A17))) -> 50.7 | N17: =IF(MAXIFS('単価履歴'!$H:$H,'単価履歴'!$E:$E,N$1,'単価履歴'!$F:$F,$A17,'単価履歴'!$O:$O, MAXIFS('単価履歴'!$O:$O,'単価履歴'!$E:$E,N$1,'単価履歴'!$F:$F,$A17))=0,"", MAXIFS('単価履歴'!$H:$H,'単価履歴'!$E:$E,N$1,'単価履歴'!$F:$F,$A17,'単価履歴'!$O:$O, MAXIFS('単価履歴'!$O:$O,'単価履歴'!$E:$E,N$1,'単価履歴'!$F:$F,$A17))) -> 42.5 | O17: =IF(MAXIFS('単価履歴'!$H:$H,'単価履歴'!$E:$E,O$1,'単価履歴'!$F:$F,$A17,'単価履歴'!$O:$O, MAXIFS('単価履歴'!$O:$O,'単価履歴'!$E:$E,O$1,'単価履歴'!$F:$F,$A17))=0,"", MAXIFS('単価履歴'!$H:$H,'単価履歴'!$E:$E,O$1,'単価履歴'!$F:$F,$A17,'単価履歴'!$O:$O, MAXIFS('単価履歴'!$O:$O,'単価履歴'!$E:$E,O$1,'単価履歴'!$F:$F,$A17))) -> 53.2 | P17: =IF(MAXIFS('単価履歴'!$H:$H,'単価履歴'!$E:$E,P$1,'単価履歴'!$F:$F,$A17,'単価履歴'!$O:$O, MAXIFS('単価履歴'!$O:$O,'単価履歴'!$E:$E,P$1,'単価履歴'!$F:$F,$A17))=0,"", MAXIFS('単価履歴'!$H:$H,'単価履歴'!$E:$E,P$1,'単価履歴'!$F:$F,$A17,'単価履歴'!$O:$O, MAXIFS('単価履歴'!$O:$O,'単価履歴'!$E:$E,P$1,'単価履歴'!$F:$F,$A17))) -> 54.5 | Q17: =IF(MAXIFS('単価履歴'!$H:$H,'単価履歴'!$E:$E,Q$1,'単価履歴'!$F:$F,$A17,'単価履歴'!$O:$O, MAXIFS('単価履歴'!$O:$O,'単価履歴'!$E:$E,Q$1,'単価履歴'!$F:$F,$A17))=0,"", MAXIFS('単価履歴'!$H:$H,'単価履歴'!$E:$E,Q$1,'単価履歴'!$F:$F,$A17,'単価履歴'!$O:$O, MAXIFS('単価履歴'!$O:$O,'単価履歴'!$E:$E,Q$1,'単価履歴'!$F:$F,$A17))) | R17: =IF(MAXIFS('単価履歴'!$H:$H,'単価履歴'!$E:$E,R$1,'単価履歴'!$F:$F,$A17,'単価履歴'!$O:$O, MAXIFS('単価履歴'!$O:$O,'単価履歴'!$E:$E,R$1,'単価履歴'!$F:$F,$A17))=0,"", MAXIFS('単価履歴'!$H:$H,'単価履歴'!$E:$E,R$1,'単価履歴'!$F:$F,$A17,'単価履歴'!$O:$O, MAXIFS('単価履歴'!$O:$O,'単価履歴'!$E:$E,R$1,'単価履歴'!$F:$F,$A17))) -> 54.2 | ... BA17: =IF(MAXIFS('単価履歴'!$H:$H,'単価履歴'!$E:$E,BA$1,'単価履歴'!$F:$F,$A17,'単価履歴'!$O:$O, MAXIFS('単価履歴'!$O:$O,'単価履歴'!$E:$E,BA$1,'単価履歴'!$F:$F,$A17))=0,"", MAXIFS('単価履歴'!$H:$H,'単価履歴'!$E:$E,BA$1,'単価履歴'!$F:$F,$A17,'単価履歴'!$O:$O, MAXIFS('単価履歴'!$O:$O,'単価履歴'!$E:$E,BA$1,'単価履歴'!$F:$F,$A17))) -> 49.5 | BC17: =IF(MAXIFS('単価履歴'!$H:$H,'単価履歴'!$E:$E,BC$1,'単価履歴'!$F:$F,$A17,'単価履歴'!$O:$O, MAXIFS('単価履歴'!$O:$O,'単価履歴'!$E:$E,BC$1,'単価履歴'!$F:$F,$A17))=0,"", MAXIFS('単価履歴'!$H:$H,'単価履歴'!$E:$E,BC$1,'単価履歴'!$F:$F,$A17,'単価履歴'!$O:$O, MAXIFS('単価履歴'!$O:$O,'単価履歴'!$E:$E,BC$1,'単価履歴'!$F:$F,$A17))) | BD17: =IF(MAXIFS('単価履歴'!$H:$H,'単価履歴'!$E:$E,BD$1,'単価履歴'!$F:$F,$A17,'単価履歴'!$O:$O, MAXIFS('単価履歴'!$O:$O,'単価履歴'!$E:$E,BD$1,'単価履歴'!$F:$F,$A17))=0,"", MAXIFS('単価履歴'!$H:$H,'単価履歴'!$E:$E,BD$1,'単価履歴'!$F:$F,$A17,'単価履歴'!$O:$O, MAXIFS('単価履歴'!$O:$O,'単価履歴'!$E:$E,BD$1,'単価履歴'!$F:$F,$A17))) | BE17: =IF(MAXIFS('単価履歴'!$H:$H,'単価履歴'!$E:$E,BE$1,'単価履歴'!$F:$F,$A17,'単価履歴'!$O:$O, MAXIFS('単価履歴'!$O:$O,'単価履歴'!$E:$E,BE$1,'単価履歴'!$F:$F,$A17))=0,"", MAXIFS('単価履歴'!$H:$H,'単価履歴'!$E:$E,BE$1,'単価履歴'!$F:$F,$A17,'単価履歴'!$O:$O, MAXIFS('単価履歴'!$O:$O,'単価履歴'!$E:$E,BE$1,'単価履歴'!$F:$F,$A17))) | BF17: =IF(MAXIFS('単価履歴'!$H:$H,'単価履歴'!$E:$E,BF$1,'単価履歴'!$F:$F,$A17,'単価履歴'!$O:$O, MAXIFS('単価履歴'!$O:$O,'単価履歴'!$E:$E,BF$1,'単価履歴'!$F:$F,$A17))=0,"", MAXIFS('単価履歴'!$H:$H,'単価履歴'!$E:$E,BF$1,'単価履歴'!$F:$F,$A17,'単価履歴'!$O:$O, MAXIFS('単価履歴'!$O:$O,'単価履歴'!$E:$E,BF$1,'単価履歴'!$F:$F,$A17))) | BG17: =IF(MAXIFS('単価履歴'!$H:$H,'単価履歴'!$E:$E,BG$1,'単価履歴'!$F:$F,$A17,'単価履歴'!$O:$O, MAXIFS('単価履歴'!$O:$O,'単価履歴'!$E:$E,BG$1,'単価履歴'!$F:$F,$A17))=0,"", MAXIFS('単価履歴'!$H:$H,'単価履歴'!$E:$E,BG$1,'単価履歴'!$F:$F,$A17,'単価履歴'!$O:$O, MAXIFS('単価履歴'!$O:$O,'単価履歴'!$E:$E,BG$1,'単価履歴'!$F:$F,$A17))) | BH17: =IF(MAXIFS('単価履歴'!$H:$H,'単価履歴'!$E:$E,BH$1,'単価履歴'!$F:$F,$A17,'単価履歴'!$O:$O, MAXIFS('単価履歴'!$O:$O,'単価履歴'!$E:$E,BH$1,'単価履歴'!$F:$F,$A17))=0,"", MAXIFS('単価履歴'!$H:$H,'単価履歴'!$E:$E,BH$1,'単価履歴'!$F:$F,$A17,'単価履歴'!$O:$O, MAXIFS('単価履歴'!$O:$O,'単価履歴'!$E:$E,BH$1,'単価履歴'!$F:$F,$A17))) | BI17: =IF(MAXIFS('単価履歴'!$H:$H,'単価履歴'!$E:$E,BI$1,'単価履歴'!$F:$F,$A17,'単価履歴'!$O:$O, MAXIFS('単価履歴'!$O:$O,'単価履歴'!$E:$E,BI$1,'単価履歴'!$F:$F,$A17))=0,"", MAXIFS('単価履歴'!$H:$H,'単価履歴'!$E:$E,BI$1,'単価履歴'!$F:$F,$A17,'単価履歴'!$O:$O, MAXIFS('単価履歴'!$O:$O,'単価履歴'!$E:$E,BI$1,'単価履歴'!$F:$F,$A17))) | BJ17: =IF(MAXIFS('単価履歴'!$H:$H,'単価履歴'!$E:$E,BJ$1,'単価履歴'!$F:$F,$A17,'単価履歴'!$O:$O, MAXIFS('単価履歴'!$O:$O,'単価履歴'!$E:$E,BJ$1,'単価履歴'!$F:$F,$A17))=0,"", MAXIFS('単価履歴'!$H:$H,'単価履歴'!$E:$E,BJ$1,'単価履歴'!$F:$F,$A17,'単価履歴'!$O:$O, MAXIFS('単価履歴'!$O:$O,'単価履歴'!$E:$E,BJ$1,'単価履歴'!$F:$F,$A17))) | ... BY17: =IF(MAXIFS('単価履歴'!$H:$H,'単価履歴'!$E:$E,BY$1,'単価履歴'!$F:$F,$A17,'単価履歴'!$O:$O, MAXIFS('単価履歴'!$O:$O,'単価履歴'!$E:$E,BY$1,'単価履歴'!$F:$F,$A17))=0,"", MAXIFS('単価履歴'!$H:$H,'単価履歴'!$E:$E,BY$1,'単価履歴'!$F:$F,$A17,'単価履歴'!$O:$O, MAXIFS('単価履歴'!$O:$O,'単価履歴'!$E:$E,BY$1,'単価履歴'!$F:$F,$A17)))
A18: Ｌ１(2級) | B18: =IF(MAXIFS('単価履歴'!$H:$H,'単価履歴'!$E:$E,B$1,'単価履歴'!$F:$F,$A18,'単価履歴'!$O:$O, MAXIFS('単価履歴'!$O:$O,'単価履歴'!$E:$E,B$1,'単価履歴'!$F:$F,$A18))=0,"", MAXIFS('単価履歴'!$H:$H,'単価履歴'!$E:$E,B$1,'単価履歴'!$F:$F,$A18,'単価履歴'!$O:$O, MAXIFS('単価履歴'!$O:$O,'単価履歴'!$E:$E,B$1,'単価履歴'!$F:$F,$A18))) -> 52.5 | C18: =IF(MAXIFS('単価履歴'!$H:$H,'単価履歴'!$E:$E,C$1,'単価履歴'!$F:$F,$A18,'単価履歴'!$O:$O, MAXIFS('単価履歴'!$O:$O,'単価履歴'!$E:$E,C$1,'単価履歴'!$F:$F,$A18))=0,"", MAXIFS('単価履歴'!$H:$H,'単価履歴'!$E:$E,C$1,'単価履歴'!$F:$F,$A18,'単価履歴'!$O:$O, MAXIFS('単価履歴'!$O:$O,'単価履歴'!$E:$E,C$1,'単価履歴'!$F:$F,$A18))) -> 51 | D18: =IF(MAXIFS('単価履歴'!$H:$H,'単価履歴'!$E:$E,D$1,'単価履歴'!$F:$F,$A18,'単価履歴'!$O:$O, MAXIFS('単価履歴'!$O:$O,'単価履歴'!$E:$E,D$1,'単価履歴'!$F:$F,$A18))=0,"", MAXIFS('単価履歴'!$H:$H,'単価履歴'!$E:$E,D$1,'単価履歴'!$F:$F,$A18,'単価履歴'!$O:$O, MAXIFS('単価履歴'!$O:$O,'単価履歴'!$E:$E,D$1,'単価履歴'!$F:$F,$A18))) -> 38.8 | G18: =IF(MAXIFS('単価履歴'!$H:$H,'単価履歴'!$E:$E,G$1,'単価履歴'!$F:$F,$A18,'単価履歴'!$O:$O, MAXIFS('単価履歴'!$O:$O,'単価履歴'!$E:$E,G$1,'単価履歴'!$F:$F,$A18))=0,"", MAXIFS('単価履歴'!$H:$H,'単価履歴'!$E:$E,G$1,'単価履歴'!$F:$F,$A18,'単価履歴'!$O:$O, MAXIFS('単価履歴'!$O:$O,'単価履歴'!$E:$E,G$1,'単価履歴'!$F:$F,$A18))) -> 53.5 | H18: =IF(MAXIFS('単価履歴'!$H:$H,'単価履歴'!$E:$E,H$1,'単価履歴'!$F:$F,$A18,'単価履歴'!$O:$O, MAXIFS('単価履歴'!$O:$O,'単価履歴'!$E:$E,H$1,'単価履歴'!$F:$F,$A18))=0,"", MAXIFS('単価履歴'!$H:$H,'単価履歴'!$E:$E,H$1,'単価履歴'!$F:$F,$A18,'単価履歴'!$O:$O, MAXIFS('単価履歴'!$O:$O,'単価履歴'!$E:$E,H$1,'単価履歴'!$F:$F,$A18))) -> 52.3 | K18: =IF(MAXIFS('単価履歴'!$H:$H,'単価履歴'!$E:$E,K$1,'単価履歴'!$F:$F,$A18,'単価履歴'!$O:$O, MAXIFS('単価履歴'!$O:$O,'単価履歴'!$E:$E,K$1,'単価履歴'!$F:$F,$A18))=0,"", MAXIFS('単価履歴'!$H:$H,'単価履歴'!$E:$E,K$1,'単価履歴'!$F:$F,$A18,'単価履歴'!$O:$O, MAXIFS('単価履歴'!$O:$O,'単価履歴'!$E:$E,K$1,'単価履歴'!$F:$F,$A18))) -> 50 | L18: =IF(MAXIFS('単価履歴'!$H:$H,'単価履歴'!$E:$E,L$1,'単価履歴'!$F:$F,$A18,'単価履歴'!$O:$O, MAXIFS('単価履歴'!$O:$O,'単価履歴'!$E:$E,L$1,'単価履歴'!$F:$F,$A18))=0,"", MAXIFS('単価履歴'!$H:$H,'単価履歴'!$E:$E,L$1,'単価履歴'!$F:$F,$A18,'単価履歴'!$O:$O, MAXIFS('単価履歴'!$O:$O,'単価履歴'!$E:$E,L$1,'単価履歴'!$F:$F,$A18))) -> 32.7 | M18: =IF(MAXIFS('単価履歴'!$H:$H,'単価履歴'!$E:$E,M$1,'単価履歴'!$F:$F,$A18,'単価履歴'!$O:$O, MAXIFS('単価履歴'!$O:$O,'単価履歴'!$E:$E,M$1,'単価履歴'!$F:$F,$A18))=0,"", MAXIFS('単価履歴'!$H:$H,'単価履歴'!$E:$E,M$1,'単価履歴'!$F:$F,$A18,'単価履歴'!$O:$O, MAXIFS('単価履歴'!$O:$O,'単価履歴'!$E:$E,M$1,'単価履歴'!$F:$F,$A18))) -> 49.7 | N18: =IF(MAXIFS('単価履歴'!$H:$H,'単価履歴'!$E:$E,N$1,'単価履歴'!$F:$F,$A18,'単価履歴'!$O:$O, MAXIFS('単価履歴'!$O:$O,'単価履歴'!$E:$E,N$1,'単価履歴'!$F:$F,$A18))=0,"", MAXIFS('単価履歴'!$H:$H,'単価履歴'!$E:$E,N$1,'単価履歴'!$F:$F,$A18,'単価履歴'!$O:$O, MAXIFS('単価履歴'!$O:$O,'単価履歴'!$E:$E,N$1,'単価履歴'!$F:$F,$A18))) -> 41.5 | O18: =IF(MAXIFS('単価履歴'!$H:$H,'単価履歴'!$E:$E,O$1,'単価履歴'!$F:$F,$A18,'単価履歴'!$O:$O, MAXIFS('単価履歴'!$O:$O,'単価履歴'!$E:$E,O$1,'単価履歴'!$F:$F,$A18))=0,"", MAXIFS('単価履歴'!$H:$H,'単価履歴'!$E:$E,O$1,'単価履歴'!$F:$F,$A18,'単価履歴'!$O:$O, MAXIFS('単価履歴'!$O:$O,'単価履歴'!$E:$E,O$1,'単価履歴'!$F:$F,$A18))) -> 52.7 | P18: =IF(MAXIFS('単価履歴'!$H:$H,'単価履歴'!$E:$E,P$1,'単価履歴'!$F:$F,$A18,'単価履歴'!$O:$O, MAXIFS('単価履歴'!$O:$O,'単価履歴'!$E:$E,P$1,'単価履歴'!$F:$F,$A18))=0,"", MAXIFS('単価履歴'!$H:$H,'単価履歴'!$E:$E,P$1,'単価履歴'!$F:$F,$A18,'単価履歴'!$O:$O, MAXIFS('単価履歴'!$O:$O,'単価履歴'!$E:$E,P$1,'単価履歴'!$F:$F,$A18))) -> 50 | Q18: =IF(MAXIFS('単価履歴'!$H:$H,'単価履歴'!$E:$E,Q$1,'単価履歴'!$F:$F,$A18,'単価履歴'!$O:$O, MAXIFS('単価履歴'!$O:$O,'単価履歴'!$E:$E,Q$1,'単価履歴'!$F:$F,$A18))=0,"", MAXIFS('単価履歴'!$H:$H,'単価履歴'!$E:$E,Q$1,'単価履歴'!$F:$F,$A18,'単価履歴'!$O:$O, MAXIFS('単価履歴'!$O:$O,'単価履歴'!$E:$E,Q$1,'単価履歴'!$F:$F,$A18))) | R18: =IF(MAXIFS('単価履歴'!$H:$H,'単価履歴'!$E:$E,R$1,'単価履歴'!$F:$F,$A18,'単価履歴'!$O:$O, MAXIFS('単価履歴'!$O:$O,'単価履歴'!$E:$E,R$1,'単価履歴'!$F:$F,$A18))=0,"", MAXIFS('単価履歴'!$H:$H,'単価履歴'!$E:$E,R$1,'単価履歴'!$F:$F,$A18,'単価履歴'!$O:$O, MAXIFS('単価履歴'!$O:$O,'単価履歴'!$E:$E,R$1,'単価履歴'!$F:$F,$A18))) | ... AQ18: =IF(MAXIFS('単価履歴'!$H:$H,'単価履歴'!$E:$E,AQ$1,'単価履歴'!$F:$F,$A18,'単価履歴'!$O:$O, MAXIFS('単価履歴'!$O:$O,'単価履歴'!$E:$E,AQ$1,'単価履歴'!$F:$F,$A18))=0,"", MAXIFS('単価履歴'!$H:$H,'単価履歴'!$E:$E,AQ$1,'単価履歴'!$F:$F,$A18,'単価履歴'!$O:$O, MAXIFS('単価履歴'!$O:$O,'単価履歴'!$E:$E,AQ$1,'単価履歴'!$F:$F,$A18))) | AT18: =IF(MAXIFS('単価履歴'!$H:$H,'単価履歴'!$E:$E,AT$1,'単価履歴'!$F:$F,$A18,'単価履歴'!$O:$O, MAXIFS('単価履歴'!$O:$O,'単価履歴'!$E:$E,AT$1,'単価履歴'!$F:$F,$A18))=0,"", MAXIFS('単価履歴'!$H:$H,'単価履歴'!$E:$E,AT$1,'単価履歴'!$F:$F,$A18,'単価履歴'!$O:$O, MAXIFS('単価履歴'!$O:$O,'単価履歴'!$E:$E,AT$1,'単価履歴'!$F:$F,$A18))) -> 50 | AU18: =IF(MAXIFS('単価履歴'!$H:$H,'単価履歴'!$E:$E,AU$1,'単価履歴'!$F:$F,$A18,'単価履歴'!$O:$O, MAXIFS('単価履歴'!$O:$O,'単価履歴'!$E:$E,AU$1,'単価履歴'!$F:$F,$A18))=0,"", MAXIFS('単価履歴'!$H:$H,'単価履歴'!$E:$E,AU$1,'単価履歴'!$F:$F,$A18,'単価履歴'!$O:$O, MAXIFS('単価履歴'!$O:$O,'単価履歴'!$E:$E,AU$1,'単価履歴'!$F:$F,$A18))) | AV18: =IF(MAXIFS('単価履歴'!$H:$H,'単価履歴'!$E:$E,AV$1,'単価履歴'!$F:$F,$A18,'単価履歴'!$O:$O, MAXIFS('単価履歴'!$O:$O,'単価履歴'!$E:$E,AV$1,'単価履歴'!$F:$F,$A18))=0,"", MAXIFS('単価履歴'!$H:$H,'単価履歴'!$E:$E,AV$1,'単価履歴'!$F:$F,$A18,'単価履歴'!$O:$O, MAXIFS('単価履歴'!$O:$O,'単価履歴'!$E:$E,AV$1,'単価履歴'!$F:$F,$A18))) -> 52.5 | AW18: =IF(MAXIFS('単価履歴'!$H:$H,'単価履歴'!$E:$E,AW$1,'単価履歴'!$F:$F,$A18,'単価履歴'!$O:$O, MAXIFS('単価履歴'!$O:$O,'単価履歴'!$E:$E,AW$1,'単価履歴'!$F:$F,$A18))=0,"", MAXIFS('単価履歴'!$H:$H,'単価履歴'!$E:$E,AW$1,'単価履歴'!$F:$F,$A18,'単価履歴'!$O:$O, MAXIFS('単価履歴'!$O:$O,'単価履歴'!$E:$E,AW$1,'単価履歴'!$F:$F,$A18))) -> 52.5 | AX18: =IF(MAXIFS('単価履歴'!$H:$H,'単価履歴'!$E:$E,AX$1,'単価履歴'!$F:$F,$A18,'単価履歴'!$O:$O, MAXIFS('単価履歴'!$O:$O,'単価履歴'!$E:$E,AX$1,'単価履歴'!$F:$F,$A18))=0,"", MAXIFS('単価履歴'!$H:$H,'単価履歴'!$E:$E,AX$1,'単価履歴'!$F:$F,$A18,'単価履歴'!$O:$O, MAXIFS('単価履歴'!$O:$O,'単価履歴'!$E:$E,AX$1,'単価履歴'!$F:$F,$A18))) | AY18: =IF(MAXIFS('単価履歴'!$H:$H,'単価履歴'!$E:$E,AY$1,'単価履歴'!$F:$F,$A18,'単価履歴'!$O:$O, MAXIFS('単価履歴'!$O:$O,'単価履歴'!$E:$E,AY$1,'単価履歴'!$F:$F,$A18))=0,"", MAXIFS('単価履歴'!$H:$H,'単価履歴'!$E:$E,AY$1,'単価履歴'!$F:$F,$A18,'単価履歴'!$O:$O, MAXIFS('単価履歴'!$O:$O,'単価履歴'!$E:$E,AY$1,'単価履歴'!$F:$F,$A18))) | AZ18: =IF(MAXIFS('単価履歴'!$H:$H,'単価履歴'!$E:$E,AZ$1,'単価履歴'!$F:$F,$A18,'単価履歴'!$O:$O, MAXIFS('単価履歴'!$O:$O,'単価履歴'!$E:$E,AZ$1,'単価履歴'!$F:$F,$A18))=0,"", MAXIFS('単価履歴'!$H:$H,'単価履歴'!$E:$E,AZ$1,'単価履歴'!$F:$F,$A18,'単価履歴'!$O:$O, MAXIFS('単価履歴'!$O:$O,'単価履歴'!$E:$E,AZ$1,'単価履歴'!$F:$F,$A18))) | BA18: =IF(MAXIFS('単価履歴'!$H:$H,'単価履歴'!$E:$E,BA$1,'単価履歴'!$F:$F,$A18,'単価履歴'!$O:$O, MAXIFS('単価履歴'!$O:$O,'単価履歴'!$E:$E,BA$1,'単価履歴'!$F:$F,$A18))=0,"", MAXIFS('単価履歴'!$H:$H,'単価履歴'!$E:$E,BA$1,'単価履歴'!$F:$F,$A18,'単価履歴'!$O:$O, MAXIFS('単価履歴'!$O:$O,'単価履歴'!$E:$E,BA$1,'単価履歴'!$F:$F,$A18))) | BC18: =IF(MAXIFS('単価履歴'!$H:$H,'単価履歴'!$E:$E,BC$1,'単価履歴'!$F:$F,$A18,'単価履歴'!$O:$O, MAXIFS('単価履歴'!$O:$O,'単価履歴'!$E:$E,BC$1,'単価履歴'!$F:$F,$A18))=0,"", MAXIFS('単価履歴'!$H:$H,'単価履歴'!$E:$E,BC$1,'単価履歴'!$F:$F,$A18,'単価履歴'!$O:$O, MAXIFS('単価履歴'!$O:$O,'単価履歴'!$E:$E,BC$1,'単価履歴'!$F:$F,$A18))) | BD18: =IF(MAXIFS('単価履歴'!$H:$H,'単価履歴'!$E:$E,BD$1,'単価履歴'!$F:$F,$A18,'単価履歴'!$O:$O, MAXIFS('単価履歴'!$O:$O,'単価履歴'!$E:$E,BD$1,'単価履歴'!$F:$F,$A18))=0,"", MAXIFS('単価履歴'!$H:$H,'単価履歴'!$E:$E,BD$1,'単価履歴'!$F:$F,$A18,'単価履歴'!$O:$O, MAXIFS('単価履歴'!$O:$O,'単価履歴'!$E:$E,BD$1,'単価履歴'!$F:$F,$A18))) | BE18: =IF(MAXIFS('単価履歴'!$H:$H,'単価履歴'!$E:$E,BE$1,'単価履歴'!$F:$F,$A18,'単価履歴'!$O:$O, MAXIFS('単価履歴'!$O:$O,'単価履歴'!$E:$E,BE$1,'単価履歴'!$F:$F,$A18))=0,"", MAXIFS('単価履歴'!$H:$H,'単価履歴'!$E:$E,BE$1,'単価履歴'!$F:$F,$A18,'単価履歴'!$O:$O, MAXIFS('単価履歴'!$O:$O,'単価履歴'!$E:$E,BE$1,'単価履歴'!$F:$F,$A18))) | BF18: =IF(MAXIFS('単価履歴'!$H:$H,'単価履歴'!$E:$E,BF$1,'単価履歴'!$F:$F,$A18,'単価履歴'!$O:$O, MAXIFS('単価履歴'!$O:$O,'単価履歴'!$E:$E,BF$1,'単価履歴'!$F:$F,$A18))=0,"", MAXIFS('単価履歴'!$H:$H,'単価履歴'!$E:$E,BF$1,'単価履歴'!$F:$F,$A18,'単価履歴'!$O:$O, MAXIFS('単価履歴'!$O:$O,'単価履歴'!$E:$E,BF$1,'単価履歴'!$F:$F,$A18))) | BG18: =IF(MAXIFS('単価履歴'!$H:$H,'単価履歴'!$E:$E,BG$1,'単価履歴'!$F:$F,$A18,'単価履歴'!$O:$O, MAXIFS('単価履歴'!$O:$O,'単価履歴'!$E:$E,BG$1,'単価履歴'!$F:$F,$A18))=0,"", MAXIFS('単価履歴'!$H:$H,'単価履歴'!$E:$E,BG$1,'単価履歴'!$F:$F,$A18,'単価履歴'!$O:$O, MAXIFS('単価履歴'!$O:$O,'単価履歴'!$E:$E,BG$1,'単価履歴'!$F:$F,$A18))) | BH18: =IF(MAXIFS('単価履歴'!$H:$H,'単価履歴'!$E:$E,BH$1,'単価履歴'!$F:$F,$A18,'単価履歴'!$O:$O, MAXIFS('単価履歴'!$O:$O,'単価履歴'!$E:$E,BH$1,'単価履歴'!$F:$F,$A18))=0,"", MAXIFS('単価履歴'!$H:$H,'単価履歴'!$E:$E,BH$1,'単価履歴'!$F:$F,$A18,'単価履歴'!$O:$O, MAXIFS('単価履歴'!$O:$O,'単価履歴'!$E:$E,BH$1,'単価履歴'!$F:$F,$A18))) | BI18: =IF(MAXIFS('単価履歴'!$H:$H,'単価履歴'!$E:$E,BI$1,'単価履歴'!$F:$F,$A18,'単価履歴'!$O:$O, MAXIFS('単価履歴'!$O:$O,'単価履歴'!$E:$E,BI$1,'単価履歴'!$F:$F,$A18))=0,"", MAXIFS('単価履歴'!$H:$H,'単価履歴'!$E:$E,BI$1,'単価履歴'!$F:$F,$A18,'単価履歴'!$O:$O, MAXIFS('単価履歴'!$O:$O,'単価履歴'!$E:$E,BI$1,'単価履歴'!$F:$F,$A18))) | BJ18: =IF(MAXIFS('単価履歴'!$H:$H,'単価履歴'!$E:$E,BJ$1,'単価履歴'!$F:$F,$A18,'単価履歴'!$O:$O, MAXIFS('単価履歴'!$O:$O,'単価履歴'!$E:$E,BJ$1,'単価履歴'!$F:$F,$A18))=0,"", MAXIFS('単価履歴'!$H:$H,'単価履歴'!$E:$E,BJ$1,'単価履歴'!$F:$F,$A18,'単価履歴'!$O:$O, MAXIFS('単価履歴'!$O:$O,'単価履歴'!$E:$E,BJ$1,'単価履歴'!$F:$F,$A18))) | ... BY18: =IF(MAXIFS('単価履歴'!$H:$H,'単価履歴'!$E:$E,BY$1,'単価履歴'!$F:$F,$A18,'単価履歴'!$O:$O, MAXIFS('単価履歴'!$O:$O,'単価履歴'!$E:$E,BY$1,'単価履歴'!$F:$F,$A18))=0,"", MAXIFS('単価履歴'!$H:$H,'単価履歴'!$E:$E,BY$1,'単価履歴'!$F:$F,$A18,'単価履歴'!$O:$O, MAXIFS('単価履歴'!$O:$O,'単価履歴'!$E:$E,BY$1,'単価履歴'!$F:$F,$A18)))
A19: Ｌ２(H4･級外･L1ﾊﾞﾗ) | B19: =IF(MAXIFS('単価履歴'!$H:$H,'単価履歴'!$E:$E,B$1,'単価履歴'!$F:$F,$A19,'単価履歴'!$O:$O, MAXIFS('単価履歴'!$O:$O,'単価履歴'!$E:$E,B$1,'単価履歴'!$F:$F,$A19))=0,"", MAXIFS('単価履歴'!$H:$H,'単価履歴'!$E:$E,B$1,'単価履歴'!$F:$F,$A19,'単価履歴'!$O:$O, MAXIFS('単価履歴'!$O:$O,'単価履歴'!$E:$E,B$1,'単価履歴'!$F:$F,$A19))) -> 48 | G19: =IF(MAXIFS('単価履歴'!$H:$H,'単価履歴'!$E:$E,G$1,'単価履歴'!$F:$F,$A19,'単価履歴'!$O:$O, MAXIFS('単価履歴'!$O:$O,'単価履歴'!$E:$E,G$1,'単価履歴'!$F:$F,$A19))=0,"", MAXIFS('単価履歴'!$H:$H,'単価履歴'!$E:$E,G$1,'単価履歴'!$F:$F,$A19,'単価履歴'!$O:$O, MAXIFS('単価履歴'!$O:$O,'単価履歴'!$E:$E,G$1,'単価履歴'!$F:$F,$A19))) -> 48 | K19: =IF(MAXIFS('単価履歴'!$H:$H,'単価履歴'!$E:$E,K$1,'単価履歴'!$F:$F,$A19,'単価履歴'!$O:$O, MAXIFS('単価履歴'!$O:$O,'単価履歴'!$E:$E,K$1,'単価履歴'!$F:$F,$A19))=0,"", MAXIFS('単価履歴'!$H:$H,'単価履歴'!$E:$E,K$1,'単価履歴'!$F:$F,$A19,'単価履歴'!$O:$O, MAXIFS('単価履歴'!$O:$O,'単価履歴'!$E:$E,K$1,'単価履歴'!$F:$F,$A19))) | L19: =IF(MAXIFS('単価履歴'!$H:$H,'単価履歴'!$E:$E,L$1,'単価履歴'!$F:$F,$A19,'単価履歴'!$O:$O, MAXIFS('単価履歴'!$O:$O,'単価履歴'!$E:$E,L$1,'単価履歴'!$F:$F,$A19))=0,"", MAXIFS('単価履歴'!$H:$H,'単価履歴'!$E:$E,L$1,'単価履歴'!$F:$F,$A19,'単価履歴'!$O:$O, MAXIFS('単価履歴'!$O:$O,'単価履歴'!$E:$E,L$1,'単価履歴'!$F:$F,$A19))) | M19: =IF(MAXIFS('単価履歴'!$H:$H,'単価履歴'!$E:$E,M$1,'単価履歴'!$F:$F,$A19,'単価履歴'!$O:$O, MAXIFS('単価履歴'!$O:$O,'単価履歴'!$E:$E,M$1,'単価履歴'!$F:$F,$A19))=0,"", MAXIFS('単価履歴'!$H:$H,'単価履歴'!$E:$E,M$1,'単価履歴'!$F:$F,$A19,'単価履歴'!$O:$O, MAXIFS('単価履歴'!$O:$O,'単価履歴'!$E:$E,M$1,'単価履歴'!$F:$F,$A19))) | N19: =IF(MAXIFS('単価履歴'!$H:$H,'単価履歴'!$E:$E,N$1,'単価履歴'!$F:$F,$A19,'単価履歴'!$O:$O, MAXIFS('単価履歴'!$O:$O,'単価履歴'!$E:$E,N$1,'単価履歴'!$F:$F,$A19))=0,"", MAXIFS('単価履歴'!$H:$H,'単価履歴'!$E:$E,N$1,'単価履歴'!$F:$F,$A19,'単価履歴'!$O:$O, MAXIFS('単価履歴'!$O:$O,'単価履歴'!$E:$E,N$1,'単価履歴'!$F:$F,$A19))) | O19: =IF(MAXIFS('単価履歴'!$H:$H,'単価履歴'!$E:$E,O$1,'単価履歴'!$F:$F,$A19,'単価履歴'!$O:$O, MAXIFS('単価履歴'!$O:$O,'単価履歴'!$E:$E,O$1,'単価履歴'!$F:$F,$A19))=0,"", MAXIFS('単価履歴'!$H:$H,'単価履歴'!$E:$E,O$1,'単価履歴'!$F:$F,$A19,'単価履歴'!$O:$O, MAXIFS('単価履歴'!$O:$O,'単価履歴'!$E:$E,O$1,'単価履歴'!$F:$F,$A19))) | P19: =IF(MAXIFS('単価履歴'!$H:$H,'単価履歴'!$E:$E,P$1,'単価履歴'!$F:$F,$A19,'単価履歴'!$O:$O, MAXIFS('単価履歴'!$O:$O,'単価履歴'!$E:$E,P$1,'単価履歴'!$F:$F,$A19))=0,"", MAXIFS('単価履歴'!$H:$H,'単価履歴'!$E:$E,P$1,'単価履歴'!$F:$F,$A19,'単価履歴'!$O:$O, MAXIFS('単価履歴'!$O:$O,'単価履歴'!$E:$E,P$1,'単価履歴'!$F:$F,$A19))) | Q19: =IF(MAXIFS('単価履歴'!$H:$H,'単価履歴'!$E:$E,Q$1,'単価履歴'!$F:$F,$A19,'単価履歴'!$O:$O, MAXIFS('単価履歴'!$O:$O,'単価履歴'!$E:$E,Q$1,'単価履歴'!$F:$F,$A19))=0,"", MAXIFS('単価履歴'!$H:$H,'単価履歴'!$E:$E,Q$1,'単価履歴'!$F:$F,$A19,'単価履歴'!$O:$O, MAXIFS('単価履歴'!$O:$O,'単価履歴'!$E:$E,Q$1,'単価履歴'!$F:$F,$A19))) | R19: =IF(MAXIFS('単価履歴'!$H:$H,'単価履歴'!$E:$E,R$1,'単価履歴'!$F:$F,$A19,'単価履歴'!$O:$O, MAXIFS('単価履歴'!$O:$O,'単価履歴'!$E:$E,R$1,'単価履歴'!$F:$F,$A19))=0,"", MAXIFS('単価履歴'!$H:$H,'単価履歴'!$E:$E,R$1,'単価履歴'!$F:$F,$A19,'単価履歴'!$O:$O, MAXIFS('単価履歴'!$O:$O,'単価履歴'!$E:$E,R$1,'単価履歴'!$F:$F,$A19))) | ... BA19: =IF(MAXIFS('単価履歴'!$H:$H,'単価履歴'!$E:$E,BA$1,'単価履歴'!$F:$F,$A19,'単価履歴'!$O:$O, MAXIFS('単価履歴'!$O:$O,'単価履歴'!$E:$E,BA$1,'単価履歴'!$F:$F,$A19))=0,"", MAXIFS('単価履歴'!$H:$H,'単価履歴'!$E:$E,BA$1,'単価履歴'!$F:$F,$A19,'単価履歴'!$O:$O, MAXIFS('単価履歴'!$O:$O,'単価履歴'!$E:$E,BA$1,'単価履歴'!$F:$F,$A19))) -> 48 | BC19: =IF(MAXIFS('単価履歴'!$H:$H,'単価履歴'!$E:$E,BC$1,'単価履歴'!$F:$F,$A19,'単価履歴'!$O:$O, MAXIFS('単価履歴'!$O:$O,'単価履歴'!$E:$E,BC$1,'単価履歴'!$F:$F,$A19))=0,"", MAXIFS('単価履歴'!$H:$H,'単価履歴'!$E:$E,BC$1,'単価履歴'!$F:$F,$A19,'単価履歴'!$O:$O, MAXIFS('単価履歴'!$O:$O,'単価履歴'!$E:$E,BC$1,'単価履歴'!$F:$F,$A19))) | BD19: =IF(MAXIFS('単価履歴'!$H:$H,'単価履歴'!$E:$E,BD$1,'単価履歴'!$F:$F,$A19,'単価履歴'!$O:$O, MAXIFS('単価履歴'!$O:$O,'単価履歴'!$E:$E,BD$1,'単価履歴'!$F:$F,$A19))=0,"", MAXIFS('単価履歴'!$H:$H,'単価履歴'!$E:$E,BD$1,'単価履歴'!$F:$F,$A19,'単価履歴'!$O:$O, MAXIFS('単価履歴'!$O:$O,'単価履歴'!$E:$E,BD$1,'単価履歴'!$F:$F,$A19))) | BE19: =IF(MAXIFS('単価履歴'!$H:$H,'単価履歴'!$E:$E,BE$1,'単価履歴'!$F:$F,$A19,'単価履歴'!$O:$O, MAXIFS('単価履歴'!$O:$O,'単価履歴'!$E:$E,BE$1,'単価履歴'!$F:$F,$A19))=0,"", MAXIFS('単価履歴'!$H:$H,'単価履歴'!$E:$E,BE$1,'単価履歴'!$F:$F,$A19,'単価履歴'!$O:$O, MAXIFS('単価履歴'!$O:$O,'単価履歴'!$E:$E,BE$1,'単価履歴'!$F:$F,$A19))) | BF19: =IF(MAXIFS('単価履歴'!$H:$H,'単価履歴'!$E:$E,BF$1,'単価履歴'!$F:$F,$A19,'単価履歴'!$O:$O, MAXIFS('単価履歴'!$O:$O,'単価履歴'!$E:$E,BF$1,'単価履歴'!$F:$F,$A19))=0,"", MAXIFS('単価履歴'!$H:$H,'単価履歴'!$E:$E,BF$1,'単価履歴'!$F:$F,$A19,'単価履歴'!$O:$O, MAXIFS('単価履歴'!$O:$O,'単価履歴'!$E:$E,BF$1,'単価履歴'!$F:$F,$A19))) | BG19: =IF(MAXIFS('単価履歴'!$H:$H,'単価履歴'!$E:$E,BG$1,'単価履歴'!$F:$F,$A19,'単価履歴'!$O:$O, MAXIFS('単価履歴'!$O:$O,'単価履歴'!$E:$E,BG$1,'単価履歴'!$F:$F,$A19))=0,"", MAXIFS('単価履歴'!$H:$H,'単価履歴'!$E:$E,BG$1,'単価履歴'!$F:$F,$A19,'単価履歴'!$O:$O, MAXIFS('単価履歴'!$O:$O,'単価履歴'!$E:$E,BG$1,'単価履歴'!$F:$F,$A19))) | BH19: =IF(MAXIFS('単価履歴'!$H:$H,'単価履歴'!$E:$E,BH$1,'単価履歴'!$F:$F,$A19,'単価履歴'!$O:$O, MAXIFS('単価履歴'!$O:$O,'単価履歴'!$E:$E,BH$1,'単価履歴'!$F:$F,$A19))=0,"", MAXIFS('単価履歴'!$H:$H,'単価履歴'!$E:$E,BH$1,'単価履歴'!$F:$F,$A19,'単価履歴'!$O:$O, MAXIFS('単価履歴'!$O:$O,'単価履歴'!$E:$E,BH$1,'単価履歴'!$F:$F,$A19))) | BI19: =IF(MAXIFS('単価履歴'!$H:$H,'単価履歴'!$E:$E,BI$1,'単価履歴'!$F:$F,$A19,'単価履歴'!$O:$O, MAXIFS('単価履歴'!$O:$O,'単価履歴'!$E:$E,BI$1,'単価履歴'!$F:$F,$A19))=0,"", MAXIFS('単価履歴'!$H:$H,'単価履歴'!$E:$E,BI$1,'単価履歴'!$F:$F,$A19,'単価履歴'!$O:$O, MAXIFS('単価履歴'!$O:$O,'単価履歴'!$E:$E,BI$1,'単価履歴'!$F:$F,$A19))) | BJ19: =IF(MAXIFS('単価履歴'!$H:$H,'単価履歴'!$E:$E,BJ$1,'単価履歴'!$F:$F,$A19,'単価履歴'!$O:$O, MAXIFS('単価履歴'!$O:$O,'単価履歴'!$E:$E,BJ$1,'単価履歴'!$F:$F,$A19))=0,"", MAXIFS('単価履歴'!$H:$H,'単価履歴'!$E:$E,BJ$1,'単価履歴'!$F:$F,$A19,'単価履歴'!$O:$O, MAXIFS('単価履歴'!$O:$O,'単価履歴'!$E:$E,BJ$1,'単価履歴'!$F:$F,$A19))) | ... BY19: =IF(MAXIFS('単価履歴'!$H:$H,'単価履歴'!$E:$E,BY$1,'単価履歴'!$F:$F,$A19,'単価履歴'!$O:$O, MAXIFS('単価履歴'!$O:$O,'単価履歴'!$E:$E,BY$1,'単価履歴'!$F:$F,$A19))=0,"", MAXIFS('単価履歴'!$H:$H,'単価履歴'!$E:$E,BY$1,'単価履歴'!$F:$F,$A19,'単価履歴'!$O:$O, MAXIFS('単価履歴'!$O:$O,'単価履歴'!$E:$E,BY$1,'単価履歴'!$F:$F,$A19)))
